Workbook

Sheet ダッシュボード
A1: 現在のフェーズ：Phase 1 データ基盤構築（進行率 約60%）
A2: Phase 1残タスク：GA4実装 / CMS構造化 / リード通知メール / 閲覧履歴UI接続 / CMS永続化 | E2: Phase 2移行条件：GA4完了 + CMS構造化完了 + 通知メール稼働 + 掲載3社+ + events 1,000件+
A4: ぺいほーむ 事業推進管理シート
A5: 最終更新: 2026-03-22
A7: 進捗サマリー
A8: カテゴリ | B8: 全タスク数 | C8: 完了 | D8: 進行中 | E8: 未着手 | F8: 完了率 | G8: 担当
A9: 事業戦略・収益化 | B9: =COUNTIF(Todo詳細!B:B,"収益")+COUNTIF(Todo詳細!B:B,"戦略") | C9: =COUNTIFS(Todo詳細!B:B,"収益",Todo詳細!K:K,"完了")+COUNTIFS(Todo詳細!B:B,"戦略",Todo詳細!K:K,"完了") | D9: =COUNTIFS(Todo詳細!B:B,"収益",Todo詳細!K:K,"進行中")+COUNTIFS(Todo詳細!B:B,"収益",Todo詳細!K:K,"確認中")+COUNTIFS(Todo詳細!B:B,"戦略",Todo詳細!K:K,"進行中")+COUNTIFS(Todo詳細!B:B,"戦略",Todo詳細!K:K,"確認中") | E9: =COUNTIFS(Todo詳細!B:B,"収益",Todo詳細!K:K,"未着手")+COUNTIFS(Todo詳細!B:B,"戦略",Todo詳細!K:K,"未着手") | F9: =IF(B9=0,"-",C9/B9) | G9: 経営
A10: 営業・アライアンス | B10: =COUNTIF(Todo詳細!B:B,"営業") | C10: =COUNTIFS(Todo詳細!B:B,"営業",Todo詳細!K:K,"完了") | D10: =COUNTIFS(Todo詳細!B:B,"営業",Todo詳細!K:K,"進行中")+COUNTIFS(Todo詳細!B:B,"営業",Todo詳細!K:K,"確認中") | E10: =COUNTIFS(Todo詳細!B:B,"営業",Todo詳細!K:K,"未着手") | F10: =IF(B10=0,"-",C10/B10) | G10: 経営/営業
A11: 掲載品質・リライト | B11: =COUNTIF(Todo詳細!B:B,"品質") | C11: =COUNTIFS(Todo詳細!B:B,"品質",Todo詳細!K:K,"完了") | D11: =COUNTIFS(Todo詳細!B:B,"品質",Todo詳細!K:K,"進行中")+COUNTIFS(Todo詳細!B:B,"品質",Todo詳細!K:K,"確認中") | E11: =COUNTIFS(Todo詳細!B:B,"品質",Todo詳細!K:K,"未着手") | F11: =IF(B11=0,"-",C11/B11) | G11: コンテンツ
A12: 集客・マーケティング | B12: =COUNTIF(Todo詳細!B:B,"集客") | C12: =COUNTIFS(Todo詳細!B:B,"集客",Todo詳細!K:K,"完了") | D12: =COUNTIFS(Todo詳細!B:B,"集客",Todo詳細!K:K,"進行中")+COUNTIFS(Todo詳細!B:B,"集客",Todo詳細!K:K,"確認中") | E12: =COUNTIFS(Todo詳細!B:B,"集客",Todo詳細!K:K,"未着手") | F12: =IF(B12=0,"-",C12/B12) | G12: マーケ
A13: オペレーション | B13: =COUNTIF(Todo詳細!B:B,"オペ") | C13: =COUNTIFS(Todo詳細!B:B,"オペ",Todo詳細!K:K,"完了") | D13: =COUNTIFS(Todo詳細!B:B,"オペ",Todo詳細!K:K,"進行中")+COUNTIFS(Todo詳細!B:B,"オペ",Todo詳細!K:K,"確認中") | E13: =COUNTIFS(Todo詳細!B:B,"オペ",Todo詳細!K:K,"未着手") | F13: =IF(B13=0,"-",C13/B13) | G13: CS/経営
A14: KPI・計測 | B14: =COUNTIF(Todo詳細!B:B,"計測")+COUNTIF(Todo詳細!B:B,"データ") | C14: =COUNTIFS(Todo詳細!B:B,"計測",Todo詳細!K:K,"完了")+COUNTIFS(Todo詳細!B:B,"データ",Todo詳細!K:K,"完了") | D14: =COUNTIFS(Todo詳細!B:B,"計測",Todo詳細!K:K,"進行中")+COUNTIFS(Todo詳細!B:B,"計測",Todo詳細!K:K,"確認中")+COUNTIFS(Todo詳細!B:B,"データ",Todo詳細!K:K,"進行中")+COUNTIFS(Todo詳細!B:B,"データ",Todo詳細!K:K,"確認中") | E14: =COUNTIFS(Todo詳細!B:B,"計測",Todo詳細!K:K,"未着手")+COUNTIFS(Todo詳細!B:B,"データ",Todo詳細!K:K,"未着手") | F14: =IF(B14=0,"-",C14/B14) | G14: PM
A15: コンテンツ制作 | B15: =COUNTIF(Todo詳細!B:B,"コンテンツ")+COUNTIF(Todo詳細!B:B,"CV") | C15: =COUNTIFS(Todo詳細!B:B,"コンテンツ",Todo詳細!K:K,"完了")+COUNTIFS(Todo詳細!B:B,"CV",Todo詳細!K:K,"完了") | D15: =COUNTIFS(Todo詳細!B:B,"コンテンツ",Todo詳細!K:K,"進行中")+COUNTIFS(Todo詳細!B:B,"コンテンツ",Todo詳細!K:K,"確認中")+COUNTIFS(Todo詳細!B:B,"CV",Todo詳細!K:K,"進行中")+COUNTIFS(Todo詳細!B:B,"CV",Todo詳細!K:K,"確認中") | E15: =COUNTIFS(Todo詳細!B:B,"コンテンツ",Todo詳細!K:K,"未着手")+COUNTIFS(Todo詳細!B:B,"CV",Todo詳細!K:K,"未着手") | F15: =IF(B15=0,"-",C15/B15) | G15: コンテンツ
A16: 合計 | B16: =SUM(B9:B15) | C16: =SUM(C9:C15) | D16: =SUM(D9:D15) | E16: =SUM(E9:E15) | F16: =IF(B16=0,"-",C16/B16) | G16: -
A18: 直近マイルストーン
A19: マイルストーン | B19: 目標日 | C19: 状態 | D19: 担当 | E19: 備考
A20: 営業提案書 完成 | B20: 2026-04-01 | C20: =VLOOKUP("T-07",Todo詳細!A:K,11,FALSE) | D20: 経営
A21: GA4計測 稼働開始 | B21: 2026-04-01 | C21: =VLOOKUP("T-09",Todo詳細!A:K,11,FALSE) | D21: PM/エンジニア
A22: 初期パートナー1社 獲得 | B22: 2026-04-15 | C22: =VLOOKUP("T-36",Todo詳細!A:K,11,FALSE) | D22: 経営/営業 | E22: 最重要
A23: 掲載品質監査 完了 | B23: 2026-04-07 | C23: =VLOOKUP("T-26",Todo詳細!A:K,11,FALSE) | D23: コンテンツ
A24: 週次KPIレポート 開始 | B24: 2026-04-07 | C24: =VLOOKUP("T-38",Todo詳細!A:K,11,FALSE) | D24: PM
A25: パートナー3社 達成 | B25: 2026-05-15 | C25: 未着手 | D25: 営業
A26: 月次売上 発生 | B26: 2026-06-15 | C26: 未着手 | D26: 経営
A27: 銀行提携 交渉開始 | B27: 2026-05-01 | C27: =VLOOKUP("T-45",Todo詳細!A:K,11,FALSE) | D27: 経営/営業 | E27: 住宅ローン特別金利
A28: 視聴者アンケート 完了 | B28: 2026-04-21 | C28: =VLOOKUP("T-51",Todo詳細!A:K,11,FALSE) | D28: 経営/マーケ | E28: ペルソナ更新に使用
A29: CS体制 構築完了 | B29: 2026-04-14 | C29: =VLOOKUP("T-52",Todo詳細!A:K,11,FALSE) | D29: 経営/CS | E29: 反響対応開始前に必須
A30: 施工事例写真 3社分確保 | B30: 2026-05-15 | C30: =VLOOKUP("T-53",Todo詳細!A:K,11,FALSE) | D30: コンテンツ/営業 | E30: 掲載品質に直結
A31: 競合分析 完了 | B31: 2026-05-07 | C31: =VLOOKUP("T-54",Todo詳細!A:K,11,FALSE) | D31: 経営/PM | E31: 営業提案の差別化根拠

Sheet フェーズ管理
A1: ぺいほーむ フェーズ管理
A3: フェーズ概要
A4: フェーズ | B4: 状態 | C4: 概要 | D4: 開始条件 | E4: 完了条件 | F4: 期間目安 | G4: 事業側の主な作業 | H4: 開発側の主な作業
A5: Phase 0 | B5: ✅ 完了 | C5: プラットフォーム基盤構築（62画面・認証・AIチャット基盤） | D5: - | E5: 全画面実装完了 | F5: 完了済み | G5: 要件定義・画面設計 | H5: フロントエンド・バックエンド全構築
A6: Phase 1 | B6: 🔧 進行中（約60%） | C6: データ基盤構築（行動追跡・チャットログ・お気に入り・GA4） | D6: Phase 0完了 | E6: GA4設置完了 + CMS構造化完了 + リード通知メール稼働 + 掲載工務店3社以上 + user_events 1,000件以上 | F6: 1〜2ヶ月 | G6: 工務店営業・掲載情報整備・GA4設計・コンテンツ品質改善 | H6: GA4実装・CMS構造化フォーム・Resendメール接続・閲覧履歴UI接続
A7: Phase 2 | B7: 📋 未着手 | C7: AI活用開始（推薦・診断・意向抽出・分析ダッシュボード） | D7: Phase 1の完了条件を全て満たす | E7: AI推薦精度検証完了 + 月間リード30件以上 + 掲載工務店10社以上 + プロフィール登録率10%以上 | F7: 3〜6ヶ月 | G7: AI推薦のフィードバック・工務店レポート設計・営業拡大・コンテンツ量産 | H7: user_profiles・比較リスト・AIチャット拡張・推薦ロジック・分析ダッシュボード
A8: Phase 3 | B8: 📋 未着手 | C8: AI本格稼働・SaaS化（AI住宅コンシェルジュ・AI営業マン・Stripe決済） | D8: Phase 2の完了条件を全て満たす | E8: AI住宅コンシェルジュ稼働 + SaaSプラン販売開始 + エリア拡大計画策定 | F8: 6〜12ヶ月 | G8: SaaS価格設定・エリア拡大戦略・パートナー拡大 | H8: AIコンシェルジュ・AI営業マン・Stripe連携・CRM連携
A10: Phase 1：データ基盤構築（詳細）
A11: ID | B11: 項目 | C11: 優先度 | D11: 状態 | E11: 担当 | F11: 事業側Todo | G11: 開発側Todo | H11: 完了基準 | I11: 備考
A12: P1-01 | B12: anonymous_id統一 | C12: S | D12: ✅ 完了 | E12: エンジニア | F12: - | G12: use-anonymous-id.ts実装済み | H12: LocalStorage生成・保存・送信 | I12: 実装済み
A13: P1-02 | B13: user_eventsテーブル + API | C13: S | D13: ✅ 完了 | E13: エンジニア | F13: - | G13: POST /api/events/track実装済み | H13: sendBeaconバッチ送信 | I13: 実装済み
A14: P1-03 | B14: chat_sessions / chat_messages保存 | C14: S | D14: ✅ 完了 | E14: エンジニア | F14: - | G14: チャットAPI拡張済み | H14: 会話ログがDBに保存される | I14: 実装済み
A15: P1-04 | B15: リード流入チャネル・直前閲覧付与 | C15: S | D15: ✅ 完了 | E15: エンジニア | F15: - | G15: inferSourceChannel実装済み | H15: リードにsource_channel, recent_views付与 | I15: 実装済み
A16: P1-05 | B16: お気に入り機能 | C16: A | D16: ✅ 完了 | E16: エンジニア | F16: - | G16: FavoriteButton + API実装済み | H16: 未ログインでも動作・ログイン後マージ | I16: 実装済み
A17: P1-06 | B17: 閲覧履歴UI接続 | C17: A | D17: ⚠️ 部分的 | E17: エンジニア | F17: - | G17: ダッシュボードUIをライブデータに接続 | H17: /dashboard/user/historyがリアルデータ表示 | I17: モックデータのまま
A18: P1-07 | B18: GA4カスタムイベント設計・実装 | C18: A | D18: ❌ 未実装 | E18: PM + エンジニア | F18: 計測すべきイベント17種の最終確認・GA4プロパティ設定 | G18: gtag()呼び出し追加・カスタムディメンション設定 | H18: 17イベントがGA4で計測できる | I18: エンジニア初タスク
A19: P1-08 | B19: CMS構造化データ項目追加 | C19: A | D19: ❌ 未実装 | E19: PM + エンジニア + 営業 | F19: 工務店に入力してもらう項目の最終決定・工務店への説明 | G19: CMS編集画面に構造化入力フォーム追加 | H19: 全掲載工務店のdesign_taste/features/suitable_for入力完了 | I19: 営業側の工務店ヒアリングと連動
A20: P1-09 | B20: Resendリード通知メール | C20: B | D20: ❌ 未実装 | E20: エンジニア | F20: 通知先メールアドレスの確認 | G20: email.ts → フォーム送信APIへの接続 | H20: リード発生時に工務店へ即時メール通知 | I20: email_notification_spec参照
A21: P1-10 | B21: CMS → Supabase永続化 | C21: B | D21: ❌ 未実装 | E21: エンジニア | F21: - | G21: TSファイルデータのSupabase移行 | H21: CMS編集がDBに保存される | I21: Phase 2の前提
A23: Phase 2：AI活用開始（詳細）
A24: ID | B24: 項目 | C24: 優先度 | D24: 状態 | E24: 担当 | F24: 事業側Todo | G24: 開発側Todo | H24: 完了基準 | I24: 備考
A25: P2-01 | B25: user_profilesテーブル | C25: B | D25: 📋 未着手 | E25: エンジニア + PM | F25: プロフィール項目の最終決定（家族構成・予算・希望エリア等） | G25: テーブル作成・API・段階的入力UI | H25: ユーザーがプロフィールを入力・更新できる | I25: 段階的プロフィール構築
A26: P2-02 | B26: 比較リスト機能 | C26: B | D26: 📋 未着手 | E26: エンジニア | F26: - | G26: 比較テーブル・API・比較UI（横並び表示） | H26: 工務店・物件を最大5件まで比較できる | I26: お気に入りと連動
A27: P2-03 | B27: AIチャット拡張（意向抽出） | C27: A | D27: 📋 未着手 | E27: PM + エンジニア | F27: 抽出すべき意向タグの定義（平屋/ZEH/デザイン等） | G27: GPT-4oプロンプト拡張・タグ抽出ロジック | H27: チャット終了時にinterest_tags自動付与 | I27: ai_chat_operation_rules参照
A28: P2-04 | B28: AIチャット拡張（工務店推薦） | C28: A | D28: 📋 未着手 | E28: PM + エンジニア | F28: 推薦ロジックのルール定義（エリア×価格×デザイン） | G28: 推薦API・構造化データとのマッチング | H28: ユーザーの条件に合う工務店を3社提案 | I28: CMS構造化データが前提
A29: P2-05 | B29: AIチャット拡張（会話要約） | C29: A | D29: 📋 未着手 | E29: エンジニア | F29: - | G29: GPT-4oによる会話要約の自動生成 | H29: chat_sessionsにconversation_summary保存 | I29: リード化時に活用
A30: P2-06 | B30: 意向データ付きリード | C30: A | D30: 📋 未着手 | E30: PM + エンジニア | F30: 工務店に共有するリード情報の最終設計 | G30: リード詳細画面に行動履歴・チャット要約・推薦理由を表示 | H30: 工務店が商談前にユーザーの意向を把握できる | I30: lead_management_rules参照
A31: P2-07 | B31: スコアリング可視化 | C31: B | D31: 📋 未着手 | E31: PM + エンジニア | F31: スコアリングルールの最終調整（重み付け） | G31: 行動データからtemperature自動計算・管理画面表示 | H31: リード一覧でHot/Warm/Cold表示 | I31: lead_management_rules参照
A32: P2-08 | B32: 管理画面分析ダッシュボード | C32: B | D32: 📋 未着手 | E32: PM + エンジニア | F32: 見たいKPIの優先順位決定 | G32: チャート・集計API・ダッシュボードUI | H32: チャット・行動・ファネル分析が閲覧できる | I32: GA4データとの連携
A33: P2-09 | B33: 工務店向けレポート基盤 | C33: B | D33: 📋 未着手 | E33: PM + 営業 + エンジニア | F33: レポートに含める項目・頻度の決定（月次想定） | G33: レポート自動生成・PDF出力・メール送信 | H33: 工務店に月次でリードレポートが届く | I33: 営業価値の核心
A34: P2-10 | B34: LINE Messaging API連携 | C34: B | D34: 📋 未着手 | E34: PM + エンジニア | F34: LINE公式アカウント設定・リッチメニュー設計 | G34: 友だち追加追跡・プッシュ通知 | H34: LINE経由のリード追跡ができる | I34: platform_operation_rules参照
A36: Phase 3：AI本格稼働・SaaS化（詳細）
A37: ID | B37: 項目 | C37: 優先度 | D37: 状態 | E37: 担当 | F37: 事業側Todo | G37: 開発側Todo | H37: 完了基準 | I37: 備考
A38: P3-01 | B38: AI住宅コンシェルジュ | C38: A | D38: 📋 未着手 | E38: PM + エンジニア | F38: コンシェルジュの対話シナリオ設計・品質基準策定 | G38: 検討フェーズ認識 + 行動文脈 + パーソナライズ対話 | H38: ユーザーの検討段階に応じた高度な対話ができる | I38: Phase 2のデータ蓄積が前提
A39: P3-02 | B39: AI営業マン | C39: A | D39: 📋 未着手 | E39: PM + 営業 + エンジニア | F39: 工務店向け提案支援のユースケース定義 | G39: 商談支援ダッシュボード・提案自動生成 | H39: 工務店がAI提案を活用して成約率向上 | I39: Phase 2の推薦ロジック改善後
A40: P3-03 | B40: 商談前要約自動生成 | C40: A | D40: 📋 未着手 | E40: エンジニア | F40: - | G40: チャット + 行動 + プロフィールの統合要約API | H40: 工務店が商談前にユーザー要約を確認できる | I40: P2-05, P2-06の延長
A41: P3-04 | B41: 営業改善SaaS | C41: B | D41: 📋 未着手 | E41: 経営 + PM | F41: SaaS機能設計・価格設定・ターゲット企業定義 | G41: 成約パターン分析・最適提案エンジン | H41: SaaSプランとして販売可能な状態 | I41: 十分な成約データが必要
A42: P3-05 | B42: Stripe決済連携 | C42: B | D42: 📋 未着手 | E42: 経営 + エンジニア | F42: 料金プラン最終確定・決済フロー設計 | G42: Stripeサブスクリプション・請求管理UI | H42: 工務店がオンラインでプラン契約・決済できる | I42: 掲載工務店10社以上が前提
A43: P3-06 | B43: CRM連携 | C43: C | D43: 📋 未着手 | E43: PM + エンジニア | F43: 工務店のCRM利用状況調査・連携先CRM選定 | G43: API連携・データ同期 | H43: 主要CRMにリード情報を自動連携 | I43: 工務店ニーズ次第
A44: P3-07 | B44: エリア拡大（九州全域→中国・四国） | C44: C | D44: 📋 未着手 | E44: 経営 + 営業 | F44: エリア拡大戦略策定・新規エリア工務店開拓 | G44: エリアフィルター拡張・コンテンツ追加 | H44: 新エリアで掲載工務店5社以上 | I44: 九州での実績確立後
...

Sheet ガントチャート
A1: ID | B1: 担当 | C1: カテゴリ | D1: タスク名 | E1: 開始日 | F1: 終了日 | G1: 日数 | H1: ステータス | I1: 進捗% | J1: W1 03/24 | K1: W2 03/31 | L1: W3 04/07 | M1: W4 04/14 | N1: W5 04/21 | O1: W6 04/28 | P1: W7 05/05 | Q1: W8 05/12 | R1: W9 05/19 | S1: W10 05/26 | T1: W11 06/02 | U1: W12 06/09
A2: 【Month 1: 基盤固め・営業開始】
A3: T-06 | B3: 経営 | C3: 戦略 | D3: エレベーターピッチ作成 | E3: 03/24 | F3: 03/28 | G3: 5 | H3: 完了 | I3: 1
A4: T-07 | B4: 経営 | C4: 営業 | D4: 営業提案書 初稿作成 | E4: 03/24 | F4: 04/04 | G4: 10 | H4: 完了 | I4: 1
A5: T-25 | B5: コンテンツ | C5: 品質 | D5: 掲載基準・フォーマット策定 | E5: 03/24 | F5: 03/31 | G5: 7 | H5: 完了 | I5: 1
A6: T-09 | B6: PM | C6: 計測 | D6: GA4セットアップ | E6: 03/24 | F6: 03/31 | G6: 7 | H6: 未着手 | I6: 0
A7: T-26 | B7: コンテンツ | C7: 品質 | D7: 全ページ文言監査 | E7: 03/24 | F7: 04/07 | G7: 14 | H7: 完了 | I7: 1
A8: T-32 | B8: 経営 | C8: オペ | D8: 問い合わせ対応フロー設計 | E8: 03/24 | F8: 04/04 | G8: 10 | H8: 完了 | I8: 1
A9: T-17 | B9: 経営 | C9: 営業 | D9: 営業提案フロー設計 | E9: 03/31 | F9: 04/07 | G9: 7 | H9: 完了 | I9: 1
A10: T-35 | B10: 経営 | C10: 収益 | D10: 料金プラン確定 | E10: 03/31 | F10: 04/07 | G10: 7 | H10: 未着手 | I10: 0
A11: T-27 | B11: コンテンツ | C11: 品質 | D11: 再ヒアリング項目整理 | E11: 03/31 | F11: 04/07 | G11: 7 | H11: 完了 | I11: 1
A12: T-04 | B12: 経営 | C12: 戦略 | D12: ペルソナ3パターン作成 | E12: 03/31 | F12: 04/07 | G12: 7 | H12: 完了 | I12: 1
A13: T-02 | B13: PM | C13: 計測 | D13: KPI定義・計測開始 | E13: 03/31 | F13: 04/07 | G13: 7 | H13: 未着手 | I13: 0
A14: T-40 | B14: 経営 | C14: 戦略 | D14: 四半期マイルストーン設定 | E14: 03/31 | F14: 04/07 | G14: 7 | H14: 未着手 | I14: 0
... A24: T-13 | B24: PM | C24: 計測 | D24: CV率計測・分析開始 | E24: 04/14 | F24: 04/21 | G24: 7 | H24: 未着手 | I24: 0
A25: 【Month 2: 拡大準備・コンテンツ充実】
A26: T-05 | B26: 営業 | C26: 戦略 | D26: 工務店ターゲットリスト作成 | E26: 04/21 | F26: 05/02 | G26: 10 | H26: 未着手 | I26: 0
A27: T-11 | B27: コンテンツ | C27: 集客 | D27: SEO記事制作(月3本) | E27: 04/21 | F27: 05/15 | G27: 24 | H27: 完了 | I27: 1
A28: T-12 | B28: マーケ | C28: 集客 | D28: LINE公式運用開始 | E28: 04/21 | F28: 05/02 | G28: 10 | H28: 未着手 | I28: 0
A29: T-20 | B29: 営業 | C29: 営業 | D29: 新規工務店アプローチ(月5社) | E29: 04/28 | F29: 05/22 | G29: 24 | H29: 未着手 | I29: 0
A30: T-22 | B30: コンテンツ | C30: コンテンツ | D30: 月次コンテンツカレンダー作成 | E30: 04/21 | F30: 04/28 | G30: 7 | H30: 完了 | I30: 1
A31: T-30 | B31: コンテンツ | C31: 品質 | D31: SEOメタデータ一括入力 | E31: 04/21 | F31: 05/02 | G31: 10 | H31: 完了 | I31: 1
A32: T-31 | B32: コンテンツ | C32: 品質 | D32: マガジン表紙画像制作 | E32: 04/28 | F32: 05/15 | G32: 17 | H32: 未着手 | I32: 0
A33: T-42 | B33: コンテンツ | C33: 品質 | D33: 構造化データ入力 | E33: 05/04 | F33: 05/22 | G33: 18 | H33: 未着手 | I33: 0
A34: T-39 | B34: PM | C34: 計測 | D34: 月次レビュー会議開始 | E34: 05/04 | F34: 05/11 | G34: 7 | H34: 完了 | I34: 1
A35: 【Month 3: 検証・改善・次フェーズ準備】
A36: T-01 | B36: 経営 | C36: 収益 | D36: 収益モデル初期検証 | E36: 05/18 | F36: 06/05 | G36: 18 | H36: 未着手 | I36: 0
A37: T-03 | B37: 経営 | C37: 戦略 | D37: 月次P/L作成 | E37: 05/18 | F37: 05/25 | G37: 7 | H37: 完了 | I37: 1
A38: T-14 | B38: PM | C38: CV | D38: フォーム離脱率分析・改善 | E38: 05/18 | F38: 06/01 | G38: 14 | H38: 未着手 | I38: 0
A39: T-15 | B39: PM | C39: データ | D39: データ活用ロードマップ確定 | E39: 05/25 | F39: 06/08 | G39: 14 | H39: 完了 | I39: 1
A40: T-16 | B40: PM | C40: データ | D40: 月次データレポート作成 | E40: 06/01 | F40: 06/15 | G40: 14 | H40: 完了 | I40: 1
A41: T-23 | B41: コンテンツ | C41: コンテンツ | D41: 比較コンテンツ制作 | E41: 05/18 | F41: 06/15 | G41: 28 | H41: 完了 | I41: 1
A42: T-24 | B42: コンテンツ | C42: コンテンツ | D42: AIチャット用FAQ整理 | E42: 05/25 | F42: 06/08 | G42: 14 | H42: 完了 | I42: 1
A43: T-41 | B43: 経営 | C43: 戦略 | D43: 年間事業計画策定 | E43: 06/01 | F43: 06/15 | G43: 14 | H43: 未着手 | I43: 0
A44: T-34 | B44: 経営 | C44: オペ | D44: SLA設定 | E44: 06/01 | F44: 06/08 | G44: 7 | H44: 完了 | I44: 1
A45: T-45 | B45: 銀行への提案（ぺいほーむ特別金利） | C45: 経営/営業 | D45: 2026-04-15 | E45: 2026-06-30 | F45: 未着手
A46: T-46 | B46: 不動産会社との提携交渉 | C46: 経営/営業 | D46: 2026-05-01 | E46: 2026-07-31 | F46: 未着手
A47: T-47 | B47: 住宅展示場・イベント出展交渉 | C47: 経営/営業 | D47: 2026-06-01 | E47: 2026-09-30 | F47: 未着手
A48: T-48 | B48: 火災保険・引越し業者アライアンス | C48: 経営/営業 | D48: 2026-07-01 | E48: 2026-09-30 | F48: 未着手
A49: T-49 | B49: 補助金・助成金情報の定期更新 | C49: コンテンツ | D49: 2026-04-01 | E49: 2026-04-30 | F49: 未着手
...

Sheet 担当別Todo
A1: 担当 | B1: ID | C1: タスク名 | D1: カテゴリ | E1: 期限 | F1: 優先度 | G1: ステータス | H1: 次のアクション | I1: 備考
A2: T-45 | B2: 経営/営業 | C2: 銀行への提案（ぺいほーむ特別金利） | D2: 中 | E2: 2026-06-30 | F2: 未着手
A3: T-46 | B3: 経営/営業 | C3: 不動産会社との提携交渉 | D3: 中 | E3: 2026-07-31 | F3: 未着手 | G3: 完了 | H3: AIで草案3パターン生成→選定
A4: T-47 | B4: 経営/営業 | C4: 住宅展示場・イベント出展交渉 | D4: 低 | E4: 2026-09-30 | F4: 未着手 | G4: 完了 | H4: AIで構成案作成→レビュー
A5: T-48 | B5: 経営/営業 | C5: 火災保険・引越し業者アライアンス | D5: 低 | E5: 2026-09-30 | F5: 未着手 | G5: 未着手 | H5: 競合調査→3プラン価格決定
A6: T-49 | B6: コンテンツ | C6: 補助金・助成金情報の定期更新 | D6: 高 | E6: 2026-04-30 | F6: 未着手 | G6: 完了 | H6: AIでフロー草案→調整
A7: T-50 | B7: マーケ | C7: Instagram運用開始 | D7: 中 | E7: 2026-05-31 | F7: 未着手 | G7: 完了 | H7: AIでフロー草案→確定
A8: T-51 | B8: 経営/マーケ | C8: 既存YouTube視聴者アンケート実施 | D8: 高 | E8: 2026-04-21 | F8: 未着手 | G8: 未着手 | H8: アポ取得→提案書持参→交渉
A9: T-52 | B9: 経営/CS | C9: カスタマーサポート体制構築 | D9: 高 | E9: 2026-04-14 | F9: 未着手 | G9: 未着手 | H9: T-19の結果→契約締結 | I9: 最重要
A10: T-53 | B10: コンテンツ/営業 | C10: 掲載工務店の施工事例写真収集 | D10: 高 | E10: 2026-05-15 | F10: 未着手 | G10: 未着手 | H10: Q2/Q3/Q4目標値設定
A11: T-54 | B11: 経営/PM | C11: 競合分析レポート作成 | D11: 中 | E11: 2026-05-07 | F11: 未着手 | G11: 未着手 | H11: 3プランの最終価格決定 | I11: 経営専権
A13: 営業 | B13: T-28 | C13: 工務店再ヒアリング(1-3社) | D13: 品質 | E13: 04/21 | F13: 高 | G13: 未着手 | H13: 質問シート(T-27)→訪問実施
A14: 営業 | B14: T-05 | C14: ターゲットリスト50社 | D14: 戦略 | E14: 05/02 | F14: 中 | G14: 未着手 | H14: AI補助でリスト収集→人間確認
A15: 営業 | B15: T-20 | C15: 新規アプローチ(月5社) | D15: 営業 | E15: 05/22 | F15: 中 | G15: 未着手 | H15: リスト→アポ→提案
A16: 営業 | B16: T-18 | C16: 契約書テンプレート | D16: 営業 | E16: 04/14 | F16: 高 | G16: 完了 | H16: AIで草案→法務確認
A18: PM | B18: T-09 | C18: GA4セットアップ | D18: 計測 | E18: 03/31 | F18: 高 | G18: 未着手 | H18: エンジニアと連携→設定完了
A19: PM | B19: T-02 | C19: KPI定義・計測開始 | D19: 計測 | E19: 04/07 | F19: 高 | G19: 未着手 | H19: 5項目選定→計測設計→稼働
A20: PM | B20: T-38 | C20: 週次KPIレポート開始 | D20: 計測 | E20: 04/21 | F20: 高 | G20: 完了 | H20: テンプレート作成→毎週実施
A21: PM | B21: T-13 | C21: CV率計測開始 | D21: CV | E21: 04/21 | F21: 中 | G21: 未着手 | H21: GA4イベント→レポート化
A22: PM | B22: T-15 | C22: データ活用ロードマップ | D22: データ | E22: 06/08 | F22: 中 | G22: 完了 | H22: AIでたたき台→経営判断
A24: マーケ | B24: T-10 | C24: YouTube概要欄CTA | D24: 集客 | E24: 04/14 | F24: 高 | G24: 完了 | H24: 全動画にWeb導線テンプレ適用
A25: マーケ | B25: T-12 | C25: LINE公式運用開始 | D25: 集客 | E25: 05/02 | F25: 中 | G25: 未着手 | H25: 開設→友だち追加導線→配信開始
A27: コンテンツ | B27: T-25 | C27: 掲載基準策定 | D27: 品質 | E27: 03/31 | F27: 高 | G27: 完了 | H27: AIでたたき台→レビュー→確定
... A31: コンテンツ | B31: T-29 | C31: リライト実施(5件) | D31: 品質 | E31: 04/25 | F31: 中 | G31: 未着手 | H31: AIで草案→人間レビュー→公開
A32: コンテンツ | B32: T-30 | C32: SEOメタデータ一括入力 | D32: 品質 | E32: 05/02 | F32: 中 | G32: 完了 | H32: AI一括生成(80件)→レビュー | I32: AI自動化◎
A33: コンテンツ | B33: T-11 | C33: SEO記事制作(月3本) | D33: 集客 | E33: 05/15 | F33: 中 | G33: 完了 | H33: AI下書き→事実確認→公開
A34: コンテンツ | B34: T-24 | C34: FAQ整理(50問) | D34: コンテンツ | E34: 06/08 | F34: 中 | G34: 完了 | H34: AI一括生成→精査→RAG投入 | I34: AI自動化◎

Sheet Todo詳細
A1: ID | B1: カテゴリ | C1: タスク名 | D1: 背景/目的 | E1: 具体的アクション | F1: 成果物 | G1: 担当 | H1: 優先度 | I1: 開始日 | J1: 期限 | K1: ステータス | L1: 進捗% | M1: 自動化 | N1: メモ | O1: 追加日 | P1: フェーズ
A2: T-01 | B2: 収益 | C2: 収益モデル初期検証 | D2: 全収益モデルが未検証 | E2: 反響課金で最初の1件を有料実施→単価・オペレーション検証 | F2: 検証結果レポート | G2: 経営 | H2: 高 | I2: 05/18 | J2: 06/05 | K2: 未着手 | L2: 0 | M2: D | O2: 2026-03-22
A3: T-02 | B3: 計測 | C3: KPI定義・計測開始 | D3: KPIが定義済みだが計測未開始 | E3: 主要5項目選定→計測設計→週次追跡 | F3: KPI一覧・計測設計書 | G3: PM | H3: 高 | I3: 03/31 | J3: 04/07 | K3: 未着手 | L3: 0 | M3: B | O3: 2026-03-22
A4: T-03 | B4: 戦略 | C4: 月次P/L作成 | D4: 収支が見える化されていない | E4: 月次の収入支出を整理→損益把握 | F4: P/Lテンプレート | G4: 経営 | H4: 高 | I4: 05/18 | J4: 05/25 | K4: 完了 | L4: 1 | M4: B | O4: 2026-03-22
A5: T-04 | B5: 戦略 | C5: ペルソナ3パターン作成 | D5: YouTube実データはあるがペルソナ未言語化 | E5: 55-64歳/45-54歳/35-44歳の3パターン具体化 | F5: ペルソナカード3枚 | G5: 経営 | H5: 高 | I5: 03/31 | J5: 04/07 | K5: 完了 | L5: 1 | M5: B | O5: 2026-03-22
A6: T-05 | B6: 戦略 | C6: 工務店ターゲットリスト50社 | D6: 営業先リストが存在しない | E6: 鹿児島・福岡中心に50社リスト作成 | F6: ターゲットリスト | G6: 営業 | H6: 中 | I6: 04/21 | J6: 05/02 | K6: 未着手 | L6: 0 | M6: C | O6: 2026-03-22
A7: T-06 | B7: 戦略 | C7: エレベーターピッチ作成 | D7: 30秒で事業を説明できる言葉がない | E7: 消費者向け/工務店向け2パターン | F7: ピッチ文書 | G7: 経営 | H7: 高 | I7: 03/24 | J7: 03/28 | K7: 完了 | L7: 1 | M7: B | O7: 2026-03-22
A8: T-07 | B8: 営業 | C8: 営業提案書作成 | D8: 営業資料がない | E8: 10-15P提案書(事業概要/プラン/料金) | F8: 提案書PDF | G8: 経営 | H8: 高 | I8: 03/24 | J8: 04/04 | K8: 完了 | L8: 1 | M8: B | O8: 2026-03-22
A9: T-08 | B9: 収益 | C9: 料金プラン確定 | D9: 料金が仮設定 | E9: 3プランの価格・内容を確定 | F9: 料金プラン表 | G9: 経営 | H9: 高 | I9: 03/31 | J9: 04/07 | K9: 未着手 | L9: 0 | M9: D | O9: 2026-03-22
A10: T-09 | B10: 計測 | C10: GA4セットアップ | D10: Webアクセスデータが取れていない | E10: GA4初期設定→主要イベント計測開始 | F10: GA4稼働 | G10: PM | H10: 高 | I10: 03/24 | J10: 03/31 | K10: 未着手 | L10: 0 | M10: C | O10: 2026-03-22
A11: T-10 | B11: 集客 | C11: YouTube概要欄CTA最適化 | D11: YouTube→Web送客導線が未最適化 | E11: 全動画概要欄にURL+CTA追加 | F11: 概要欄テンプレート | G11: マーケ | H11: 高 | I11: 04/07 | J11: 04/14 | K11: 完了 | L11: 1 | M11: B | O11: 2026-03-22
A12: T-11 | B12: 集客 | C12: SEO記事追加(月3本) | D12: 検索流入が未開拓 | E12: キーワード調査→構成→下書き→公開 | F12: 記事3本/月 | G12: コンテンツ | H12: 中 | I12: 04/21 | J12: 05/15 | K12: 未着手 | L12: 0% | M12: B | O12: 2026-03-22
A13: T-12 | B13: 集客 | C13: LINE公式運用開始 | D13: LINEでのCRM未稼働 | E13: 開設→友だち追加導線→週次配信 | F13: LINE運用計画 | G13: マーケ | H13: 中 | I13: 04/21 | J13: 05/02 | K13: 未着手 | L13: 0 | M13: C | O13: 2026-03-22
A14: T-13 | B14: CV | C14: CV率計測・分析開始 | D14: CV率が不明 | E14: 各フォームCV率+チャット転換率を計測 | F14: CV率レポート | G14: PM | H14: 高 | I14: 04/14 | J14: 04/21 | K14: 未着手 | L14: 0 | M14: B | O14: 2026-03-22
A15: T-14 | B15: CV | C15: フォーム離脱率分析 | D15: 離脱ポイント不明 | E15: GA4でフォーム到達→送信の離脱率計測 | F15: 離脱分析レポート | G15: PM | H15: 中 | I15: 05/18 | J15: 06/01 | K15: 未着手 | L15: 0 | M15: C | O15: 2026-03-22
A16: T-15 | B16: データ | C16: データ活用ロードマップ | D16: データ活用方針が未確定 | E16: 四半期ごとの活用計画定義 | F16: ロードマップ文書 | G16: PM | H16: 中 | I16: 05/25 | J16: 06/08 | K16: 完了 | L16: 1 | M16: B | O16: 2026-03-22
A17: T-16 | B17: データ | C17: 月次データレポート作成 | D17: 分析レポートの仕組みなし | E17: 行動/チャット/CV/リード品質の雛形 | F17: レポートテンプレート | G17: PM | H17: 中 | I17: 06/01 | J17: 06/15 | K17: 完了 | L17: 1 | M17: A | O17: 2026-03-22
A18: T-17 | B18: 営業 | C18: 営業提案フロー設計 | D18: 提案→契約フロー未設計 | E18: 初回接触→提案→トライアル→契約 | F18: 営業フロー図 | G18: 経営 | H18: 高 | I18: 03/31 | J18: 04/07 | K18: 完了 | L18: 1 | M18: B | O18: 2026-03-22
A19: T-18 | B19: 営業 | C19: 契約書テンプレート作成 | D19: 契約書がない | E19: 掲載契約/反響課金契約テンプレート | F19: 契約書テンプレート | G19: 経営 | H19: 高 | I19: 04/07 | J19: 04/14 | K19: 完了 | L19: 1 | M19: B | O19: 2026-03-22
A20: T-19 | B20: 営業 | C20: 既存取材先へのパートナー提案 | D20: 取材関係のみで有料化していない | E20: 取材実績工務店にプラン提案 | F20: 提案記録 | G20: 経営 | H20: 高 | I20: 04/07 | J20: 04/18 | K20: 未着手 | L20: 0 | M20: D | O20: 2026-03-22
A21: T-20 | B21: 営業 | C21: 新規工務店アプローチ(月5社) | D21: 新規営業先がない | E21: リスト→月5社アプローチ | F21: 営業活動記録 | G21: 営業 | H21: 中 | I21: 04/28 | J21: 05/22 | K21: 未着手 | L21: 0 | M21: D | O21: 2026-03-22
A22: T-21 | B22: 品質 | C22: 取材記事の実名化 | D22: 社名が仮名(○○工務店) | E22: 掲載許可交渉→実名差し替え | F22: 実名化済み記事 | G22: コンテンツ | H22: 高 | I22: 04/07 | J22: 04/18 | K22: 未着手 | L22: 0 | M22: D | O22: 2026-03-22
A23: T-22 | B23: コンテンツ | C23: 月次コンテンツカレンダー | D23: 制作計画がない | E23: 月次で記事3+動画4+ニュース2の計画 | F23: カレンダー | G23: コンテンツ | H23: 中 | I23: 04/21 | J23: 04/28 | K23: 完了 | L23: 1 | M23: B | O23: 2026-03-22
A24: T-23 | B24: コンテンツ | C24: 比較コンテンツ制作 | D24: 比較記事がない | E24: 工務店比較/性能比較記事3本制作 | F24: 比較記事3本 | G24: コンテンツ | H24: 中 | I24: 05/18 | J24: 06/15 | K24: 完了 | L24: 1 | M24: B | O24: 2026-03-22
A25: T-24 | B25: コンテンツ | C25: AIチャット用FAQ整理 | D25: AI回答精度の知識ベース未整理 | E25: FAQ50問+工務店ナレッジ整理 | F25: FAQ一覧 | G25: コンテンツ | H25: 中 | I25: 05/25 | J25: 06/08 | K25: 未着手 | L25: 0% | M25: A | O25: 2026-03-22
A26: T-25 | B26: 品質 | C26: 掲載基準・フォーマット策定 | D26: 掲載基準がない | E26: 必須/推奨項目・表現ルール策定 | F26: 掲載基準書 | G26: コンテンツ | H26: 高 | I26: 03/24 | J26: 03/31 | K26: 完了 | L26: 1 | M26: B | O26: 2026-03-22
A27: T-26 | B27: 品質 | C27: 全ページ文言監査 | D27: 品質・一貫性が未確認 | E27: 全ページ巡回→問題リスト化 | F27: 監査シート | G27: コンテンツ | H27: 高 | I27: 03/24 | J27: 04/07 | K27: 確認中 | L27: 40% | M27: B | O27: 2026-03-22
A28: T-27 | B28: 品質 | C28: 再ヒアリング項目整理 | D28: 不足情報の整理 | E28: 質問シート作成 | F28: 質問シート | G28: コンテンツ | H28: 高 | I28: 03/31 | J28: 04/07 | K28: 確認中 | L28: 40% | M28: B | O28: 2026-03-22
A29: T-28 | B29: 品質 | C29: 工務店再ヒアリング実施 | D29: 実データ化のため | E29: パートナー候補にヒアリング | F29: 記録 | G29: 営業 | H29: 高 | I29: 04/07 | J29: 04/21 | K29: 未着手 | L29: 0 | M29: D | O29: 2026-03-22
A30: T-29 | B30: 品質 | C30: リライト実施(優先5件) | D30: 品質改善 | E30: 監査結果→リライト→公開 | F30: リライト完了 | G30: コンテンツ | H30: 中 | I30: 04/14 | J30: 04/25 | K30: 未着手 | L30: 0 | M30: B | O30: 2026-03-22
A31: T-30 | B31: 品質 | C31: SEOメタデータ一括入力 | D31: メタデータ大部分未入力 | E31: AI一括生成(80件)→レビュー | F31: 入力完了 | G31: コンテンツ | H31: 中 | I31: 04/21 | J31: 05/02 | K31: 完了 | L31: 1 | M31: A | O31: 2026-03-22
A32: T-31 | B32: 品質 | C32: マガジン表紙画像制作 | D32: 表紙画像が全号欠如 | E32: デザイン制作(8点) | F32: 表紙画像8点 | G32: コンテンツ | H32: 中 | I32: 04/28 | J32: 05/15 | K32: 未着手 | L32: 0 | M32: C | O32: 2026-03-22
A33: T-32 | B33: オペ | C33: 問い合わせ対応フロー設計 | D33: 対応フローがない | E33: 受信→対応→紹介→フォロー設計 | F33: フロー図+マニュアル | G33: 経営 | H33: 高 | I33: 03/24 | J33: 04/04 | K33: 完了 | L33: 1 | M33: B | O33: 2026-03-22
A34: T-33 | B34: オペ | C34: 反響受け渡しフロー設計 | D34: リード共有の仕組みなし | E34: 共有方法・タイミング・フォーマット設計 | F34: フロー図 | G34: 経営 | H34: 高 | I34: 04/14 | J34: 04/21 | K34: 完了 | L34: 1 | M34: B | O34: 2026-03-22
A35: T-34 | B35: オペ | C35: SLA設定 | D35: 対応スピード基準なし | E35: 初期対応時間・紹介までの日数定義 | F35: SLA定義書 | G35: 経営 | H35: 中 | I35: 06/01 | J35: 06/08 | K35: 完了 | L35: 1 | M35: C | O35: 2026-03-22
A36: T-35 | B36: 収益 | C36: 初期プラン価格確定 | D36: 料金が仮設定 | E36: 競合調査→原価計算→3プラン価格確定 | F36: 確定料金プラン | G36: 経営 | H36: 高 | I36: 03/31 | J36: 04/07 | K36: 未着手 | L36: 0 | M36: D | O36: 2026-03-22
A37: T-36 | B37: 収益 | C37: 初期パートナー1社獲得 | D37: 売上実績ゼロ | E37: 取材先から有料パートナー獲得 | F37: 契約書+請求書 | G37: 経営 | H37: 高 | I37: 04/14 | J37: 04/25 | K37: 未着手 | L37: 0 | M37: D | O37: 2026-03-22
A38: T-37 | B38: 収益 | C38: 請求・入金フロー構築 | D38: 請求の仕組みなし | E38: 請求書発行→入金確認→消込 | F38: フロー+テンプレート | G38: 経営 | H38: 中 | I38: 04/28 | J38: 05/09 | K38: 完了 | L38: 1 | M38: B | O38: 2026-03-22
A39: T-38 | B39: 計測 | C39: 週次KPIレポート開始 | D39: KPIを追う習慣なし | E39: 毎週月曜15分ミーティング設定 | F39: テンプレート+会議体 | G39: PM | H39: 高 | I39: 04/14 | J39: 04/21 | K39: 完了 | L39: 1 | M39: A | O39: 2026-03-22
A40: T-39 | B40: 計測 | C40: 月次レビュー会議設定 | D40: 月次振り返りの場なし | E40: 毎月末1時間の定型会議 | F40: アジェンダテンプレート | G40: PM | H40: 中 | I40: 05/04 | J40: 05/11 | K40: 完了 | L40: 1 | M40: A | O40: 2026-03-22
...

Sheet 追加Todo受付
A1: 追加日 | B1: 起票者 | C1: カテゴリ | D1: タスク名 | E1: 背景/目的 | F1: 優先度(仮) | G1: 希望期限 | H1: 担当(案) | I1: 承認 | J1: Todo一覧に反映 | K1: 備考

Sheet 使い方ガイド
A1: 事業管理 使い方ガイド
A2: ぺいほーむ事業全体のタスク管理・進捗管理ファイルです。毎週のKPIミーティングとタスク確認に使用します。
A4: シート名 | B4: 用途・使い方 | C4: 更新頻度
A5: ダッシュボード | B5: 全体の進捗サマリー。カテゴリ別の完了率が自動計算される。毎週月曜に確認 | C5: 週次
A6: ガントチャート | B6: 12週間のタスクスケジュール。オレンジバーが稼働週。ステータスと進捗%を毎週更新 | C6: 週次
A7: 担当別Todo | B7: 経営/営業/PM/マーケ/コンテンツの担当ごとにタスクを確認。「次のアクション」列が最重要 | C7: 週次
A8: Todo詳細 | B8: 全44タスクの詳細情報。追加Todoは下部の空行に追記可能（T-45以降） | C8: 随時
A9: 追加Todo受付 | B9: 新しいTodoが発生したらここに起票→経営承認→Todo詳細に転記 | C9: 随時
A11: 関連ファイル
A12: payhome_project_management.xlsx | B12: 事業全体のTodo・ガントチャート・進捗管理
A13: payhome_sales.xlsx | B13: 営業提案フロー・メールDM・工務店ヒアリング・ペルソナ
A14: payhome_content.xlsx | B14: コンテンツカレンダー・YouTube戦略・動画企画・掲載監査
A15: payhome_finance_kpi.xlsx | B15: 月次P/L・KPIレポート・請求・データ活用ロードマップ
A16: payhome_sales_deck.pptx | B16: 営業提案書（PowerPoint）
A17: contract_template.docx | B17: 契約書テンプレート（Word）
A18: listing_standards.docx | B18: 掲載基準書・品質管理ガイド（Word）
A19: operations_manual.docx | B19: オペレーションマニュアル（Word）
