Workbook

Sheet ダッシュボード
A1: ぺいほーむ 事業推進管理シート
A2: 最終更新: 2026-03-22
A4: 進捗サマリー
A5: カテゴリ | B5: 全タスク数 | C5: 完了 | D5: 進行中 | E5: 未着手 | F5: 完了率 | G5: 担当
A6: 事業戦略・収益化 | B6: =COUNTIF('Todo詳細'!B:B,"収益")+COUNTIF('Todo詳細'!B:B,"戦略") | C6: =COUNTIFS('Todo詳細'!B:B,"収益",'Todo詳細'!K:K,"完了")+COUNTIFS('Todo詳細'!B:B,"戦略",'Todo詳細'!K:K,"完了") | D6: =COUNTIFS('Todo詳細'!B:B,"収益",'Todo詳細'!K:K,"進行中")+COUNTIFS('Todo詳細'!B:B,"戦略",'Todo詳細'!K:K,"進行中") | E6: =COUNTIFS('Todo詳細'!B:B,"収益",'Todo詳細'!K:K,"未着手")+COUNTIFS('Todo詳細'!B:B,"戦略",'Todo詳細'!K:K,"未着手") | F6: =IF(B6=0,"-",C6/B6) | G6: 経営
A7: 営業・アライアンス | B7: =COUNTIF('Todo詳細'!B:B,"営業") | C7: =COUNTIFS('Todo詳細'!B:B,"営業",'Todo詳細'!K:K,"完了") | D7: =COUNTIFS('Todo詳細'!B:B,"営業",'Todo詳細'!K:K,"進行中") | E7: =COUNTIFS('Todo詳細'!B:B,"営業",'Todo詳細'!K:K,"未着手") | F7: =IF(B7=0,"-",C7/B7) | G7: 経営/営業
A8: 掲載品質・リライト | B8: =COUNTIF('Todo詳細'!B:B,"品質") | C8: =COUNTIFS('Todo詳細'!B:B,"品質",'Todo詳細'!K:K,"完了") | D8: =COUNTIFS('Todo詳細'!B:B,"品質",'Todo詳細'!K:K,"進行中") | E8: =COUNTIFS('Todo詳細'!B:B,"品質",'Todo詳細'!K:K,"未着手") | F8: =IF(B8=0,"-",C8/B8) | G8: コンテンツ
A9: 集客・マーケティング | B9: =COUNTIF('Todo詳細'!B:B,"集客") | C9: =COUNTIFS('Todo詳細'!B:B,"集客",'Todo詳細'!K:K,"完了") | D9: =COUNTIFS('Todo詳細'!B:B,"集客",'Todo詳細'!K:K,"進行中") | E9: =COUNTIFS('Todo詳細'!B:B,"集客",'Todo詳細'!K:K,"未着手") | F9: =IF(B9=0,"-",C9/B9) | G9: マーケ
A10: オペレーション | B10: =COUNTIF('Todo詳細'!B:B,"オペ") | C10: =COUNTIFS('Todo詳細'!B:B,"オペ",'Todo詳細'!K:K,"完了") | D10: =COUNTIFS('Todo詳細'!B:B,"オペ",'Todo詳細'!K:K,"進行中") | E10: =COUNTIFS('Todo詳細'!B:B,"オペ",'Todo詳細'!K:K,"未着手") | F10: =IF(B10=0,"-",C10/B10) | G10: CS/経営
A11: KPI・計測 | B11: =COUNTIF('Todo詳細'!B:B,"計測")+COUNTIF('Todo詳細'!B:B,"データ")+COUNTIF('Todo詳細'!B:B,"CV") | C11: =COUNTIFS('Todo詳細'!B:B,"計測",'Todo詳細'!K:K,"完了")+COUNTIFS('Todo詳細'!B:B,"データ",'Todo詳細'!K:K,"完了")+COUNTIFS('Todo詳細'!B:B,"CV",'Todo詳細'!K:K,"完了") | D11: =COUNTIFS('Todo詳細'!B:B,"計測",'Todo詳細'!K:K,"進行中")+COUNTIFS('Todo詳細'!B:B,"データ",'Todo詳細'!K:K,"進行中")+COUNTIFS('Todo詳細'!B:B,"CV",'Todo詳細'!K:K,"進行中") | E11: =COUNTIFS('Todo詳細'!B:B,"計測",'Todo詳細'!K:K,"未着手")+COUNTIFS('Todo詳細'!B:B,"データ",'Todo詳細'!K:K,"未着手")+COUNTIFS('Todo詳細'!B:B,"CV",'Todo詳細'!K:K,"未着手") | F11: =IF(B11=0,"-",C11/B11) | G11: PM
A12: コンテンツ制作 | B12: =COUNTIF('Todo詳細'!B:B,"コンテンツ") | C12: =COUNTIFS('Todo詳細'!B:B,"コンテンツ",'Todo詳細'!K:K,"完了") | D12: =COUNTIFS('Todo詳細'!B:B,"コンテンツ",'Todo詳細'!K:K,"進行中") | E12: =COUNTIFS('Todo詳細'!B:B,"コンテンツ",'Todo詳細'!K:K,"未着手") | F12: =IF(B12=0,"-",C12/B12) | G12: コンテンツ
A13: 合計 | B13: =SUM(B6:B12) | C13: =SUM(C6:C12) | D13: =SUM(D6:D12) | E13: =SUM(E6:E12) | F13: =IF(B13=0,"-",C13/B13) | G13: -
A15: 直近マイルストーン
A16: マイルストーン | B16: 目標日 | C16: 状態 | D16: 担当 | E16: 備考
A17: 営業提案書 完成 | B17: 2026-04-01 | C17: 未着手 | D17: 経営
A18: GA4計測 稼働開始 | B18: 2026-04-01 | C18: 未着手 | D18: PM/エンジニア
A19: 初期パートナー1社 獲得 | B19: 2026-04-15 | C19: 未着手 | D19: 経営/営業 | E19: 最重要
A20: 掲載品質監査 完了 | B20: 2026-04-07 | C20: 未着手 | D20: コンテンツ
A21: 週次KPIレポート 開始 | B21: 2026-04-07 | C21: 未着手 | D21: PM
A22: パートナー3社 達成 | B22: 2026-05-15 | C22: 未着手 | D22: 営業
A23: 月次売上 発生 | B23: 2026-06-15 | C23: 未着手 | D23: 経営

Sheet ガントチャート
A1: ID | B1: 担当 | C1: カテゴリ | D1: タスク名 | E1: 開始日 | F1: 終了日 | G1: 日数 | H1: ステータス | I1: 進捗% | J1: W1 03/24 | K1: W2 03/31 | L1: W3 04/07 | M1: W4 04/14 | N1: W5 04/21 | O1: W6 04/28 | P1: W7 05/05 | Q1: W8 05/12 | R1: W9 05/19 | S1: W10 05/26 | T1: W11 06/02 | U1: W12 06/09
A2: 【Month 1: 基盤固め・営業開始】
A3: T-06 | B3: 経営 | C3: 戦略 | D3: エレベーターピッチ作成 | E3: 03/24 | F3: 03/28 | G3: 5 | H3: 未着手 | I3: 0
A4: T-07 | B4: 経営 | C4: 営業 | D4: 営業提案書 初稿作成 | E4: 03/24 | F4: 04/04 | G4: 10 | H4: 未着手 | I4: 0
A5: T-25 | B5: コンテンツ | C5: 品質 | D5: 掲載基準・フォーマット策定 | E5: 03/24 | F5: 03/31 | G5: 7 | H5: 未着手 | I5: 0
A6: T-09 | B6: PM | C6: 計測 | D6: GA4セットアップ | E6: 03/24 | F6: 03/31 | G6: 7 | H6: 未着手 | I6: 0
A7: T-26 | B7: コンテンツ | C7: 品質 | D7: 全ページ文言監査 | E7: 03/24 | F7: 04/07 | G7: 14 | H7: 未着手 | I7: 0
A8: T-32 | B8: 経営 | C8: オペ | D8: 問い合わせ対応フロー設計 | E8: 03/24 | F8: 04/04 | G8: 10 | H8: 未着手 | I8: 0
A9: T-17 | B9: 経営 | C9: 営業 | D9: 営業提案フロー設計 | E9: 03/31 | F9: 04/07 | G9: 7 | H9: 未着手 | I9: 0
A10: T-35 | B10: 経営 | C10: 収益 | D10: 料金プラン確定 | E10: 03/31 | F10: 04/07 | G10: 7 | H10: 未着手 | I10: 0
A11: T-27 | B11: コンテンツ | C11: 品質 | D11: 再ヒアリング項目整理 | E11: 03/31 | F11: 04/07 | G11: 7 | H11: 未着手 | I11: 0
A12: T-04 | B12: 経営 | C12: 戦略 | D12: ペルソナ3パターン作成 | E12: 03/31 | F12: 04/07 | G12: 7 | H12: 未着手 | I12: 0
A13: T-02 | B13: PM | C13: 計測 | D13: KPI定義・計測開始 | E13: 03/31 | F13: 04/07 | G13: 7 | H13: 未着手 | I13: 0
A14: T-40 | B14: 経営 | C14: 戦略 | D14: 四半期マイルストーン設定 | E14: 03/31 | F14: 04/07 | G14: 7 | H14: 未着手 | I14: 0
... A24: T-13 | B24: PM | C24: 計測 | D24: CV率計測・分析開始 | E24: 04/14 | F24: 04/21 | G24: 7 | H24: 未着手 | I24: 0
A25: 【Month 2: 拡大準備・コンテンツ充実】
A26: T-05 | B26: 営業 | C26: 戦略 | D26: 工務店ターゲットリスト作成 | E26: 04/21 | F26: 05/02 | G26: 10 | H26: 未着手 | I26: 0
A27: T-11 | B27: コンテンツ | C27: 集客 | D27: SEO記事制作(月3本) | E27: 04/21 | F27: 05/15 | G27: 24 | H27: 未着手 | I27: 0
A28: T-12 | B28: マーケ | C28: 集客 | D28: LINE公式運用開始 | E28: 04/21 | F28: 05/02 | G28: 10 | H28: 未着手 | I28: 0
A29: T-20 | B29: 営業 | C29: 営業 | D29: 新規工務店アプローチ(月5社) | E29: 04/28 | F29: 05/22 | G29: 24 | H29: 未着手 | I29: 0
A30: T-22 | B30: コンテンツ | C30: コンテンツ | D30: 月次コンテンツカレンダー作成 | E30: 04/21 | F30: 04/28 | G30: 7 | H30: 未着手 | I30: 0
A31: T-30 | B31: コンテンツ | C31: 品質 | D31: SEOメタデータ一括入力 | E31: 04/21 | F31: 05/02 | G31: 10 | H31: 未着手 | I31: 0
A32: T-31 | B32: コンテンツ | C32: 品質 | D32: マガジン表紙画像制作 | E32: 04/28 | F32: 05/15 | G32: 17 | H32: 未着手 | I32: 0
A33: T-42 | B33: コンテンツ | C33: 品質 | D33: 構造化データ入力 | E33: 05/04 | F33: 05/22 | G33: 18 | H33: 未着手 | I33: 0
A34: T-39 | B34: PM | C34: 計測 | D34: 月次レビュー会議開始 | E34: 05/04 | F34: 05/11 | G34: 7 | H34: 未着手 | I34: 0
A35: 【Month 3: 検証・改善・次フェーズ準備】
A36: T-01 | B36: 経営 | C36: 収益 | D36: 収益モデル初期検証 | E36: 05/18 | F36: 06/05 | G36: 18 | H36: 未着手 | I36: 0
A37: T-03 | B37: 経営 | C37: 戦略 | D37: 月次P/L作成 | E37: 05/18 | F37: 05/25 | G37: 7 | H37: 未着手 | I37: 0
A38: T-14 | B38: PM | C38: CV | D38: フォーム離脱率分析・改善 | E38: 05/18 | F38: 06/01 | G38: 14 | H38: 未着手 | I38: 0
A39: T-15 | B39: PM | C39: データ | D39: データ活用ロードマップ確定 | E39: 05/25 | F39: 06/08 | G39: 14 | H39: 未着手 | I39: 0
A40: T-16 | B40: PM | C40: データ | D40: 月次データレポート作成 | E40: 06/01 | F40: 06/15 | G40: 14 | H40: 未着手 | I40: 0
A41: T-23 | B41: コンテンツ | C41: コンテンツ | D41: 比較コンテンツ制作 | E41: 05/18 | F41: 06/15 | G41: 28 | H41: 未着手 | I41: 0
A42: T-24 | B42: コンテンツ | C42: コンテンツ | D42: AIチャット用FAQ整理 | E42: 05/25 | F42: 06/08 | G42: 14 | H42: 未着手 | I42: 0
A43: T-41 | B43: 経営 | C43: 戦略 | D43: 年間事業計画策定 | E43: 06/01 | F43: 06/15 | G43: 14 | H43: 未着手 | I43: 0
A44: T-34 | B44: 経営 | C44: オペ | D44: SLA設定 | E44: 06/01 | F44: 06/08 | G44: 7 | H44: 未着手 | I44: 0

Sheet 担当別Todo
A1: 担当 | B1: ID | C1: タスク名 | D1: カテゴリ | E1: 期限 | F1: 優先度 | G1: ステータス | H1: 次のアクション | I1: 備考
A3: 経営 | B3: T-06 | C3: エレベーターピッチ作成 | D3: 戦略 | E3: 03/28 | F3: 高 | G3: 未着手 | H3: AIで草案3パターン生成→選定
A4: 経営 | B4: T-07 | C4: 営業提案書 初稿 | D4: 営業 | E4: 04/04 | F4: 高 | G4: 未着手 | H4: AIで構成案作成→レビュー
A5: 経営 | B5: T-35 | C5: 料金プラン確定 | D5: 収益 | E5: 04/07 | F5: 高 | G5: 未着手 | H5: 競合調査→3プラン価格決定
A6: 経営 | B6: T-17 | C6: 営業フロー設計 | D6: 営業 | E6: 04/07 | F6: 高 | G6: 未着手 | H6: AIでフロー草案→調整
A7: 経営 | B7: T-32 | C7: 問い合わせ対応フロー | D7: オペ | E7: 04/04 | F7: 高 | G7: 未着手 | H7: AIでフロー草案→確定
A8: 経営 | B8: T-19 | C8: 既存取材先への提案 | D8: 営業 | E8: 04/18 | F8: 高 | G8: 未着手 | H8: アポ取得→提案書持参→交渉
A9: 経営 | B9: T-36 | C9: 初期パートナー1社獲得 | D9: 収益 | E9: 04/25 | F9: 高 | G9: 未着手 | H9: T-19の結果→契約締結 | I9: 最重要
A10: 経営 | B10: T-40 | C10: 四半期マイルストーン | D10: 戦略 | E10: 04/07 | F10: 高 | G10: 未着手 | H10: Q2/Q3/Q4目標値設定
A11: 経営 | B11: T-08 | C11: 料金プラン確定 | D11: 収益 | E11: 04/07 | F11: 高 | G11: 未着手 | H11: 3プランの最終価格決定 | I11: 経営専権
A13: 営業 | B13: T-28 | C13: 工務店再ヒアリング(1-3社) | D13: 品質 | E13: 04/21 | F13: 高 | G13: 未着手 | H13: 質問シート(T-27)→訪問実施
A14: 営業 | B14: T-05 | C14: ターゲットリスト50社 | D14: 戦略 | E14: 05/02 | F14: 中 | G14: 未着手 | H14: AI補助でリスト収集→人間確認
A15: 営業 | B15: T-20 | C15: 新規アプローチ(月5社) | D15: 営業 | E15: 05/22 | F15: 中 | G15: 未着手 | H15: リスト→アポ→提案
A16: 営業 | B16: T-18 | C16: 契約書テンプレート | D16: 営業 | E16: 04/14 | F16: 高 | G16: 未着手 | H16: AIで草案→法務確認
A18: PM | B18: T-09 | C18: GA4セットアップ | D18: 計測 | E18: 03/31 | F18: 高 | G18: 未着手 | H18: エンジニアと連携→設定完了
A19: PM | B19: T-02 | C19: KPI定義・計測開始 | D19: 計測 | E19: 04/07 | F19: 高 | G19: 未着手 | H19: 5項目選定→計測設計→稼働
A20: PM | B20: T-38 | C20: 週次KPIレポート開始 | D20: 計測 | E20: 04/21 | F20: 高 | G20: 未着手 | H20: テンプレート作成→毎週実施
A21: PM | B21: T-13 | C21: CV率計測開始 | D21: CV | E21: 04/21 | F21: 中 | G21: 未着手 | H21: GA4イベント→レポート化
A22: PM | B22: T-15 | C22: データ活用ロードマップ | D22: データ | E22: 06/08 | F22: 中 | G22: 未着手 | H22: AIでたたき台→経営判断
A24: マーケ | B24: T-10 | C24: YouTube概要欄CTA | D24: 集客 | E24: 04/14 | F24: 高 | G24: 未着手 | H24: 全動画にWeb導線テンプレ適用
A25: マーケ | B25: T-12 | C25: LINE公式運用開始 | D25: 集客 | E25: 05/02 | F25: 中 | G25: 未着手 | H25: 開設→友だち追加導線→配信開始
A27: コンテンツ | B27: T-25 | C27: 掲載基準策定 | D27: 品質 | E27: 03/31 | F27: 高 | G27: 未着手 | H27: AIでたたき台→レビュー→確定
... A31: コンテンツ | B31: T-29 | C31: リライト実施(5件) | D31: 品質 | E31: 04/25 | F31: 中 | G31: 未着手 | H31: AIで草案→人間レビュー→公開
A32: コンテンツ | B32: T-30 | C32: SEOメタデータ一括入力 | D32: 品質 | E32: 05/02 | F32: 中 | G32: 未着手 | H32: AI一括生成(80件)→レビュー | I32: AI自動化◎
A33: コンテンツ | B33: T-11 | C33: SEO記事制作(月3本) | D33: 集客 | E33: 05/15 | F33: 中 | G33: 未着手 | H33: AI下書き→事実確認→公開
A34: コンテンツ | B34: T-24 | C34: FAQ整理(50問) | D34: コンテンツ | E34: 06/08 | F34: 中 | G34: 未着手 | H34: AI一括生成→精査→RAG投入 | I34: AI自動化◎

Sheet Todo詳細
A1: ID | B1: カテゴリ | C1: タスク名 | D1: 背景/目的 | E1: 具体的アクション | F1: 成果物 | G1: 担当 | H1: 優先度 | I1: 開始日 | J1: 期限 | K1: ステータス | L1: 進捗% | M1: 自動化 | N1: メモ | O1: 追加日
A2: T-01 | B2: 収益 | C2: 収益モデル初期検証 | D2: 全収益モデルが未検証 | E2: 反響課金で最初の1件を有料実施→単価・オペレーション検証 | F2: 検証結果レポート | G2: 経営 | H2: 高 | I2: 05/18 | J2: 06/05 | K2: 未着手 | L2: 0 | M2: D | O2: 2026-03-22
A3: T-02 | B3: 計測 | C3: KPI定義・計測開始 | D3: KPIが定義済みだが計測未開始 | E3: 主要5項目選定→計測設計→週次追跡 | F3: KPI一覧・計測設計書 | G3: PM | H3: 高 | I3: 03/31 | J3: 04/07 | K3: 未着手 | L3: 0 | M3: B | O3: 2026-03-22
A4: T-03 | B4: 戦略 | C4: 月次P/L作成 | D4: 収支が見える化されていない | E4: 月次の収入支出を整理→損益把握 | F4: P/Lテンプレート | G4: 経営 | H4: 高 | I4: 05/18 | J4: 05/25 | K4: 未着手 | L4: 0 | M4: B | O4: 2026-03-22
A5: T-04 | B5: 戦略 | C5: ペルソナ3パターン作成 | D5: YouTube実データはあるがペルソナ未言語化 | E5: 55-64歳/45-54歳/35-44歳の3パターン具体化 | F5: ペルソナカード3枚 | G5: 経営 | H5: 高 | I5: 03/31 | J5: 04/07 | K5: 未着手 | L5: 0 | M5: B | O5: 2026-03-22
A6: T-05 | B6: 戦略 | C6: 工務店ターゲットリスト50社 | D6: 営業先リストが存在しない | E6: 鹿児島・福岡中心に50社リスト作成 | F6: ターゲットリスト | G6: 営業 | H6: 中 | I6: 04/21 | J6: 05/02 | K6: 未着手 | L6: 0 | M6: C | O6: 2026-03-22
A7: T-06 | B7: 戦略 | C7: エレベーターピッチ作成 | D7: 30秒で事業を説明できる言葉がない | E7: 消費者向け/工務店向け2パターン | F7: ピッチ文書 | G7: 経営 | H7: 高 | I7: 03/24 | J7: 03/28 | K7: 未着手 | L7: 0 | M7: B | O7: 2026-03-22
A8: T-07 | B8: 営業 | C8: 営業提案書作成 | D8: 営業資料がない | E8: 10-15P提案書(事業概要/プラン/料金) | F8: 提案書PDF | G8: 経営 | H8: 高 | I8: 03/24 | J8: 04/04 | K8: 未着手 | L8: 0 | M8: B | O8: 2026-03-22
A9: T-08 | B9: 収益 | C9: 料金プラン確定 | D9: 料金が仮設定 | E9: 3プランの価格・内容を確定 | F9: 料金プラン表 | G9: 経営 | H9: 高 | I9: 03/31 | J9: 04/07 | K9: 未着手 | L9: 0 | M9: D | O9: 2026-03-22
A10: T-09 | B10: 計測 | C10: GA4セットアップ | D10: Webアクセスデータが取れていない | E10: GA4初期設定→主要イベント計測開始 | F10: GA4稼働 | G10: PM | H10: 高 | I10: 03/24 | J10: 03/31 | K10: 未着手 | L10: 0 | M10: C | O10: 2026-03-22
A11: T-10 | B11: 集客 | C11: YouTube概要欄CTA最適化 | D11: YouTube→Web送客導線が未最適化 | E11: 全動画概要欄にURL+CTA追加 | F11: 概要欄テンプレート | G11: マーケ | H11: 高 | I11: 04/07 | J11: 04/14 | K11: 未着手 | L11: 0 | M11: B | O11: 2026-03-22
A12: T-11 | B12: 集客 | C12: SEO記事追加(月3本) | D12: 検索流入が未開拓 | E12: キーワード調査→構成→下書き→公開 | F12: 記事3本/月 | G12: コンテンツ | H12: 中 | I12: 04/21 | J12: 05/15 | K12: 未着手 | L12: 0 | M12: B | O12: 2026-03-22
A13: T-12 | B13: 集客 | C13: LINE公式運用開始 | D13: LINEでのCRM未稼働 | E13: 開設→友だち追加導線→週次配信 | F13: LINE運用計画 | G13: マーケ | H13: 中 | I13: 04/21 | J13: 05/02 | K13: 未着手 | L13: 0 | M13: C | O13: 2026-03-22
... A45: T-44 | B45: 品質 | C45: 物件ページ画像整備 | D45: 写真がプレースホルダー | E45: 実写真撮影/収集→差し替え | F45: 物件写真 | G45: コンテンツ | H45: 中 | I45: 05/18 | J45: 06/15 | K45: 未着手 | L45: 0 | M45: D | O45: 2026-03-22
A46: T-45
A47: T-46
A48: T-47
A49: T-48
A50: T-49
A51: T-50
A52: T-51
A53: T-52
A54: T-53
A55: T-54

Sheet メール営業管理
A1: ID | B1: 工務店名 | C1: エリア | D1: 規模(年間棟数) | E1: 平屋実績 | F1: メールアドレス | G1: 送信日 | H1: 件名 | I1: テンプレート | J1: 開封確認 | K1: 返信有無 | L1: 返信内容 | M1: 次のアクション | N1: ステータス | O1: 担当 | P1: 備考
A2: M-01 | B2: （候補A） | C2: 鹿児島市 | D2: 50棟 | E2: 平屋比率高 | H2: YouTubeコラボ提案 | I2: A:初回提案 | N2: 未送信 | O2: 営業 | P2: 取材実績あり
A3: M-02 | B3: （候補B） | C3: 鹿児島市 | D3: 80棟 | E3: 平屋あり | H3: 掲載提案 | I3: A:初回提案 | N3: 未送信 | O3: 営業
A4: M-03 | B4: （候補C） | C4: 福岡市 | D4: 60棟 | E4: 平屋あり | H4: 掲載提案 | I4: A:初回提案 | N4: 未送信 | O4: 営業
A5: M-04
A6: M-05
A7: M-06
A8: M-07
A9: M-08
A10: M-09
A11: M-10
A12: M-11
A13: M-12
A14: M-13
A15: M-14
A16: M-15
... A24: M-23

Sheet メールテンプレート
A1: テンプレートID | B1: 用途 | C1: 件名 | D1: 本文（概要） | E1: 送信タイミング | F1: 備考
A2: A:初回提案 | B2: 新規工務店への初回メールDM | C2: 【ぺいほーむ】平屋専門メディアより掲載のご提案｜YouTube4.29万人 | D2: ○○工務店 ご担当者様 突然のご連絡失礼いたします。 鹿児島を拠点に、平屋専門の住宅メディア「ぺいほーむ」を運営しております、株式会社wazekaの村田と申します。 ぺいほーむは、YouTubeチャンネル登録者4.29万人、月間視聴回数19万回以上の平屋専門メディアです。 鹿児島・九州エリアで平屋をご検討中の方々に、ルームツアー動画や記事を通じて情報をお届けしております。 この度、貴社の平屋住宅の施工実績とこだわりに注目し、ぺいほーむへの掲載をご提案したくご連絡差し上げました。 ■ ぺいほーむの特徴 ・平屋ルームツアー動画257本公開（再生数最大99万回） ・視聴者の64%が45〜64歳（建て替え・セカンドライフ検討層） ・視聴者の54%が女性（住宅購入の意思決定に大きく関与） ・Webプラットフォームでの無料相談・資料請求・見学会予約の導線あり ■ ご提案内容 貴社の平屋住宅をぺいほーむで紹介させていただくパートナープランをご用意しております。 ・ルームツアー動画の撮影・制作 ・Webプラットフォームへの工務店情報掲載 ・平屋検討者からの反響（問い合わせ）のお届け ・SNS運用代行 初回は無料でルームツアー動画を1本撮影させていただくことも可能です。 まずは15分ほどのオンラインミーティングで、貴社のお取り組みや課題をお聞かせいただければ幸いです。 ご興味がございましたら、本メールへのご返信、または下記よりお気軽にご連絡ください。 ▼ ぺいほーむ Web https://payhome-media.com/biz ▼ LINE公式 https://line.me/R/ti/p/@253gzmoh 何卒よろしくお願いいたします。 株式会社wazeka ぺいほーむ パートナー担当 村田 峻之介 Email: info@payhome.jp TEL: xxx-xxxx-xxxx | E2: リスト作成後、月5社ペース | F2: 工務店名・特徴を調べてカスタマイズして送信。「貴社の○○に注目し」の部分を具体的に
A3: B:フォローアップ | B3: 初回送信後7日で未返信の場合 | C3: 【ぺいほーむ】先日のご提案について（リマインド） | D3: ○○工務店 ご担当者様 先日、平屋専門メディア「ぺいほーむ」よりご提案のメールをお送りさせていただきました、株式会社wazekaの村田です。 お忙しい中大変恐縮ですが、ご確認いただけましたでしょうか。 実は先日、ぺいほーむで撮影した平屋のルームツアー動画が公開1週間で20万回再生を突破いたしました。 平屋への関心が非常に高まっていることを日々実感しております。 貴社の素敵な平屋住宅を、ぜひ多くの方にご紹介させていただきたいと考えております。 ■ 最近の実績 ・最新動画「おひとり様の理想を叶えた平家」: 公開8日で20万回視聴 ・人気No.1動画「小さなかわいい平屋」: 99万回視聴 ・月間チャンネル視聴回数: 19万回以上 まずは15分のオンラインミーティングからで結構です。 貴社のご都合のよい日時をお知らせいただければ幸いです。 何卒よろしくお願いいたします。 株式会社wazeka 村田 峻之介 | E3: 初回送信の7日後 | F3: 最新の動画実績を1つ追加して具体性を出す
A4: C:取材提案 | B4: 取材実績のある工務店へのパートナー化提案 | C4: 【ぺいほーむ】取材ご協力のお礼と今後のパートナーシップのご相談 | D4: ○○工務店 ○○様 いつもお世話になっております。 ぺいほーむの村田です。 先日は貴社の素敵な平屋住宅の撮影にご協力いただき、誠にありがとうございました。 おかげさまで公開した動画は○万回再生を突破し、多くの視聴者から反響をいただいております。 ■ 撮影動画の実績 ・再生回数: ○万回 ・高評価: ○件 ・コメント: ○件（「この工務店に相談したい」等の声多数） この実績を踏まえ、本日は貴社とのパートナーシップについてご相談させていただきたくご連絡いたしました。 ぺいほーむでは現在、パートナー工務店様向けに以下のサービスを提供しております。 ■ パートナープランの内容 1. Webプラットフォームへの貴社専用ページ掲載 2. 平屋検討者からの問い合わせ（反響）を直接お届け 3. 定期的なルームツアー動画撮影（月1〜2本） 4. SNS運用代行（Instagram/YouTube） 5. 月次の反響レポート 月額30,000円〜のプランをご用意しておりますが、これまでの取材関係を踏まえ、特別な条件でのご提案も可能です。 一度お時間をいただき、詳しくご説明させていただけますでしょうか。 対面でもオンラインでも、貴社のご都合に合わせます。 引き続きよろしくお願いいたします。 株式会社wazeka 村田 峻之介 | E4: 取材動画公開後1-2週間 | F4: 動画の再生数・コメントの具体数値を入れる。特別条件を匂わせて興味を引く
A5: D:事例共有 | B5: 興味を示した工務店への詳細資料送付 | C5: 【ぺいほーむ】パートナー事例と詳細資料をお送りします | D5: ○○工務店 ○○様 先日はお忙しい中お時間をいただき、ありがとうございました。 ぺいほーむの村田です。 ご関心をいただいた件について、詳細資料をお送りいたします。 ■ 添付資料 1. ぺいほーむ パートナープログラム提案書（PDF） 2. 料金プラン詳細 3. 導入事例 ■ パートナー工務店の成果（一例） ・A工務店様: ルームツアー動画月1本制作→半年で問い合わせ月3件→15件に増加 ・B工務店様: Web掲載+SNS運用→資料請求が2.8倍に ・反響単価: 業界平均8,000〜15,000円 → ぺいほーむ経由は5,000円以下 ■ 次のステップ ご検討いただいた上で、以下のいずれかで進めさせていただければ幸いです。 (1) 1ヶ月無料トライアルからスタート (2) まずはルームツアー動画1本を無料で撮影 (3) オンラインで詳細のご説明（30分程度） ご不明点がございましたら、お気軽にご連絡ください。 株式会社wazeka 村田 峻之介 | E5: 商談後・興味表明後 | F5: 提案書PDFを必ず添付。事例の数値は最新のものに更新
A6: E:トライアル案内 | B6: 商談に進んだ工務店への無料トライアル詳細 | C6: 【ぺいほーむ】1ヶ月無料トライアルの詳細をお送りします | D6: ○○工務店 ○○様 お世話になっております。 ぺいほーむの村田です。 先日のお打ち合わせにて、1ヶ月無料トライアルにご興味をいただきありがとうございます。 詳細をまとめましたのでお送りいたします。 ■ 無料トライアルの内容（1ヶ月間） ・ぺいほーむWebプラットフォームへの貴社ページ掲載 ・ルームツアー動画1本の撮影・制作・YouTube公開 ・トライアル期間中の反響（問い合わせ）は全て無料でお届け ・期間終了後にレポートをお渡しし、継続をご判断いただきます ■ トライアル開始までの流れ 1. 本メールへのご返信で参加表明（本日〜） 2. 撮影日程の調整（1週間以内） 3. 掲載情報のヒアリング（オンライン30分） 4. 撮影実施 5. 動画公開＋Webページ掲載開始 6. 1ヶ月後にレポート共有＋継続のご相談 ■ ご準備いただきたいもの ・撮影可能な完成物件または施工事例の写真5-10枚 ・会社概要（設立年/施工実績/対応エリア/得意分野） ・掲載したい情報（価格帯/デザインテイスト/性能情報） ■ 費用について トライアル期間中は完全無料です。 期間終了後、月額30,000円〜のプランをご提案しますが、継続の義務はございません。 ご参加いただける場合は、本メールに「参加希望」とご返信いただくだけで結構です。 折り返し撮影日程の調整をさせていただきます。 何卒よろしくお願いいたします。 株式会社wazeka 村田 峻之介 | E6: 商談実施後 | F6: 無料トライアルの具体的なステップを明示して行動のハードルを下げる

Sheet 掲載内容監査
A1: ID | B1: ページ種別 | C1: ページ名 | D1: 問題点 | E1: 不足情報 | F1: 修正優先度 | G1: 担当 | H1: ステータス | I1: 備考
A2: A-01 | B2: 工務店一覧 | C2: builders | D2: 全12社サンプルデータ。実名でない | E2: 電話/Web/説明/実績 | F2: 高 | G2: 営業 | H2: 未着手 | I2: 最優先
A3: A-02 | B3: 物件詳細 | C3: property/* | D3: 写真がプレースホルダー | E3: 実写真 | F3: 中 | G3: コンテンツ | H3: 未着手 | I3: YouTube動画でカバー可
A4: A-03 | B4: 取材記事 | C4: interview/* | D4: 社名が仮名(○○工務店) | E4: 実名 | F4: 高 | G4: 営業 | H4: 未着手 | I4: 掲載許可交渉必要
A5: A-04 | B5: お客様の声 | C5: voice/* | D5: 匿名(A様等)。実在性未確認 | E5: 実在確認 | F5: 中 | G5: コンテンツ | H5: 未着手
A6: A-05 | B6: 記事(9本) | C6: articles/* | D6: SEOメタ未入力 | E6: サムネ/メタ | F6: 中 | G6: コンテンツ | H6: 未着手 | I6: AI一括生成可
A7: A-06 | B7: ニュース(10本) | C7: news/* | D7: status未入力 | E7: メタデータ | F7: 低 | G7: コンテンツ | H7: 未着手
A8: A-07 | B8: 月刊誌(8号) | C8: magazine/* | D8: 表紙画像全号欠如 | E8: 表紙画像8点 | F8: 中 | G8: コンテンツ | H8: 未着手 | I8: デザイン制作必要
A9: A-08 | B9: 相談ページ | C9: consultation | D9: コピー最終調整要 | E9: なし | F9: 中 | G9: マーケ | H9: 未着手 | I9: CV率に直結
A10: A-09 | B10: トップページ | C10: home | D10: キャッチコピー調整要 | E10: なし | F10: 中 | G10: マーケ | H10: 未着手 | I10: 第一印象
A11: A-10 | B11: Bizトップ | C11: biz | D11: 事例が仮データ可能性 | E11: 実事例 | F11: 中 | G11: 営業 | H11: 未着手 | I11: B2B入口

Sheet 工務店ヒアリング管理
A1: ID | B1: 工務店名 | C1: 確認項目 | D1: 目的 | E1: 不足情報 | F1: 方法 | G1: 担当 | H1: 期限 | I1: 状況 | J1: 備考
A2: H-01 | B2: （候補A） | C2: 会社概要/設立年/代表者 | D2: 掲載基本情報 | E2: 全項目未取得 | F2: 訪問/オンライン | G2: 営業 | I2: 未着手
A3: H-02 | B3: （候補A） | C3: 平屋 年間施工数/比率 | D3: 平屋特化の根拠 | E3: 未取得 | F3: 訪問/オンライン | G3: 営業 | I3: 未着手
A4: H-03 | B4: （候補A） | C4: 価格帯(坪単価/総額) | D4: 予算マッチング | E4: 未取得 | F4: 訪問/オンライン | G4: 営業 | I4: 未着手
A5: H-04 | B5: （候補A） | C5: デザインテイスト | D5: AI推薦用 | E5: 未取得 | F5: 訪問/オンライン | G5: 営業 | I5: 未着手
A6: H-05 | B6: （候補A） | C6: 性能仕様(断熱/耐震) | D6: 性能比較 | E6: 未取得 | F6: 訪問/オンライン | G6: 営業 | I6: 未着手
A7: H-06 | B7: （候補A） | C7: 得意な間取り/特徴 | D7: コンテンツ素材 | E7: 未取得 | F7: 訪問/オンライン | G7: 営業 | I7: 未着手
A8: H-07 | B8: （候補A） | C8: 対応エリア | D8: マッチング | E8: 未取得 | F8: 訪問/オンライン | G8: 営業 | I8: 未着手
A9: H-08 | B9: （候補A） | C9: 向いている顧客像 | D9: AI推薦 | E9: 未取得 | F9: 訪問/オンライン | G9: 営業 | I9: 未着手
A10: H-09 | B10: （候補A） | C10: 写真素材(3-5枚) | D10: ビジュアル | E10: 未取得 | F10: データ提供 | G10: 営業 | I10: 未着手
A11: H-10 | B11: （候補A） | C11: 掲載文の確認 | D11: 正確性 | E11: 掲載文未作成 | F11: メール | G11: コンテンツ | I11: 未着手

Sheet 追加Todo受付
A1: 追加日 | B1: 起票者 | C1: カテゴリ | D1: タスク名 | E1: 背景/目的 | F1: 優先度(仮) | G1: 希望期限 | H1: 担当(案) | I1: 承認 | J1: Todo一覧に反映 | K1: 備考

Sheet 使い方ガイド
A1: このスプレッドシートの使い方
A3: シート名 | B3: 用途・使い方
A4: ダッシュボード | B4: 全体の進捗を俯瞰するシート。毎週月曜のKPIミーティングで確認。完了率は自動計算。
A5: ガントチャート | B5: 12週間のタスクスケジュール。オレンジのバーが稼働週。ステータスと進捗%を毎週更新する。
A6: 担当別Todo | B6: 担当者ごとにタスクを確認するシート。各メンバーが自分の担当分を見る。「次のアクション」列が最も重要。
A7: Todo詳細 | B7: 全44タスクの詳細一覧。追加Todoは下部の空行に追記可能（T-45以降）。
A8: メール営業管理 | B8: 工務店へのメールDM営業を管理。送信日・開封・返信・次アクションを追跡する。
A9: メールテンプレート | B9: メール営業で使うテンプレート5パターン。Claudeで工務店ごとにカスタマイズして使用。
A10: 掲載内容監査 | B10: プラットフォーム全ページの品質監査結果。優先度「高」から順に修正する。
A11: 工務店ヒアリング管理 | B11: パートナー候補工務店への確認項目を管理。1社につき10項目のテンプレート。
A12: 追加Todo受付 | B12: 新しいTodoが発生したらここに起票。承認後にTodo詳細に転記する。
A14: 運用ルール
A15: 1 | B15: 毎週月曜にダッシュボード+ガントチャートを確認（15分）
A16: 2 | B16: 各担当は週頭に「担当別Todo」で自分のタスクを確認し、ステータスを更新
A17: 3 | B17: メール営業は「メール営業管理」シートで月5社ペースで管理
A18: 4 | B18: 新しいTodoは「追加Todo受付」に起票→経営承認→Todo詳細に転記
A19: 5 | B19: 毎月末に「ダッシュボード」の進捗サマリーを更新し、月次レビュー会議で使用
A21: ステータスの定義
A22: 未着手 | B22: まだ着手していない
A23: 進行中 | B23: 作業中
A24: 確認中 | B24: 成果物のレビュー・確認待ち
A25: 完了 | B25: 完了
A26: 保留 | B26: 一時停止（理由をメモに記載）
A28: 自動化判定の定義
A29: A | B29: Claude/AIでほぼ自動化可能（草案生成・一括処理）
A30: B | B30: AIで叩き台作成可能、人間レビュー必須
A31: C | B31: AI補助は可能だが、人間主導で進めるべき
A32: D | B32: 人間が実行すべき（交渉・意思決定・現場作業）

Sheet YouTube戦略
A1: ぺいほーむ YouTube戦略分析
A3: 現在のチャンネルパフォーマンス
A4: 指標 | B4: 数値 | C4: 備考
A5: チャンネル登録者 | B5: 42,841人
A6: 公開動画数 | B6: 257本 | C6: 全て平屋ルームツアー
A7: 月間視聴回数 | B7: 152,228回 | C7: 過去28日間
A8: 月間再生時間 | B8: 7,722.7時間
A9: 平均視聴時間 | B9: 3分03秒
A10: 新規視聴者比率 | B10: 84.8% | C10: 未登録者92.3%→登録促進の余地大
A11: モバイル比率 | B11: 49.4% | C11: サムネ・テロップはスマホ最適化必須
A12: 女性比率 | B12: 54% | C12: 女性目線のコンテンツが響く
A13: 最多年齢層 | B13: 55-64歳 (35.3%) | C13: セカンドライフ・老後の平屋需要
A14: 2番目年齢層 | B14: 45-54歳 (29.1%) | C14: 子育て後の建て替え需要
A16: 動画別 再生数分析 — 伸びる家の選定基準
A17: 順位 | B17: タイトル | C17: 再生数 | D17: 間取り | E17: 価格 | F17: 坪数 | G17: 伸びた要因分析 | H17: カテゴリ
A18: 1 | B18: 小さなかわいい平屋 | C18: 99万 | D18: 3LDK | E18: 1,980万 | F18: 25坪 | G18: 「小さい」+「かわいい」の最強組み合わせ。女性54%の視聴者に刺さる。シンプルで覚えやすいタイトル | H18: かわいい系
A19: 2 | B19: 老後も安心して過ごせる最先端の平屋 | C19: 91万 | D19: 2LDK | E19: 2,880万 | F19: 32坪 | G19: 最多視聴者層(55-64歳)のど真ん中ニーズ。「安心」という感情訴求+「最先端」で新しさ | H19: 老後安心系
A20: 3 | B20: 完璧な間取りのお洒落で超かわいい平屋 | C20: 78万 | D20: 3LDK | E20: 2,580万 | F20: 30坪 | G20: 「完璧」「超かわいい」の強い形容詞スタック。間取りへの関心を刺激 | H20: かわいい系
A21: 4 | B21: 超有名な一級建築家の作る天才的な平屋 | C21: 59万 | D21: 3LDK | E21: 4,200万 | F21: 38坪 | G21: 権威性（一級建築家）+驚き（天才的）。価格が高くても「建築家」で納得感 | H21: 権威・驚き系
A22: 5 | B22: お値段大公開！20坪の小さな高性能平屋 | C22: 59万 | D22: 2LDK | E22: 1,580万 | F22: 20坪 | G22: 価格透明性への強い需要。「お値段大公開」で好奇心を刺激。小さい+高性能の対比 | H22: 価格公開系
A23: 6 | B23: 完全に大人の女性に似合う平屋！ | C23: 50万 | D23: 3LDK | E23: 2,780万 | F23: 32坪 | G23: ターゲット明確化（大人の女性）。視聴者の54%が女性→自分ごと化しやすい | H23: 女性ターゲット系
A24: 7 | B24: 嘘だろ...これが平屋はヤバすぎる！ | C24: 47万 | D24: 4LDK | E24: 3,500万 | F24: 42坪 | G24: 驚き・衝撃系フック。「嘘だろ」「ヤバすぎる」で好奇心を煽る | H24: 驚き系
A25: 8 | B25: 令和時代に超人気な間取りの平屋 | C25: 47万 | D25: 3LDK | E25: 2,480万 | F25: 30坪 | G25: 時代性（令和）+社会的証明（超人気）。トレンド感で関心を引く | H25: トレンド系
A26: 9 | B26: えっヤバすぎ！これはもはや平屋ではない。 | C26: 47万 | D26: 4LDK+S | E26: 3,800万 | F26: 45坪 | G26: 驚き系フック。「平屋ではない」で常識を覆す好奇心。大型で豪華 | H26: 驚き系
A27: 10 | B27: 女性設計士の作るボーホーインテリアのかわいい平屋 | C27: 44万 | D27: 3LDK | E27: 2,380万 | F27: 28坪 | G27: 「女性設計士」で共感+専門テイスト名（ボーホー）。やや専門的で層が限定 | H27: デザイン系
A28: 11 | B28: シンプルおしゃれの小さく可愛い平屋 | C28: 40万 | D28: 2LDK | E28: 1,880万 | F28: 22坪 | G28: キーワードは良いが差別化弱い。「シンプル」「おしゃれ」は汎用的すぎる | H28: かわいい系
A30: 勝ちパターン分析 — タイトル・テーマ・選定の法則
A31: パターン | B31: 再生数傾向 | C31: タイトルの特徴 | D31: 具体例 | E31: 視聴者心理 | F31: 推奨頻度 | G31: 注意点
A32: ①かわいい/おしゃれ系 | B32: 40万-99万（最強） | C32: 「かわいい」「おしゃれ」+サイズ感 | D32: 小さなかわいい平屋 | E32: 女性54%の視聴者が「自分の家もこうしたい」と感情移入 | F32: 月2本 | G32: 毎回「かわいい」だけだと飽きる。切り口を変える
A33: ②老後安心/バリアフリー系 | B33: 91万（2位） | C33: 「安心」「老後」+機能性 | D33: 老後も安心して過ごせる最先端の平屋 | E33: 最多層(55-64歳)が「将来の自分の家」として視聴 | F33: 月1本 | G33: 暗くならないよう「最先端」「快適」等ポジティブ表現と組み合わせ
A34: ③価格公開/コスパ系 | B34: 59万 | C34: 「お値段大公開」「○○万円」と金額を明示 | D34: お値段大公開！20坪の小さな高性能平屋 | E34: 「いくらで建てられるか」は全層共通の最大関心事 | F34: 月1本 | G34: 安い家だけでなく「この性能でこの値段」の対比が重要
A35: ④驚き/衝撃系 | B35: 47万-59万 | C35: 「嘘だろ」「ヤバすぎる」「天才的」 | D35: 嘘だろ...これが平屋はヤバすぎる！ | E35: 好奇心を刺激してクリック率を上げる | F35: 月1本 | G35: 毎回驚きだと信頼性が下がる。実際に驚く家を選ぶこと
A36: ⑤女性ターゲット明示系 | B36: 44万-50万 | C36: 「女性に似合う」「女性設計士」 | D36: 完全に大人の女性に似合う平屋！ | E36: 女性視聴者が「私向けだ」と自分ごと化 | F36: 月1本 | G36: 男性を排除しない表現に注意。「夫婦で」等の表現も有効
A37: ⑥トレンド/時代系 | B37: 47万 | C37: 「令和」「2026年最新」「今人気」 | D37: 令和時代に超人気な間取りの平屋 | E37: 「今これが流行っている」という社会的証明 | F37: 月1本 | G37: 具体的なトレンド名を入れると刺さる（ZEH/断熱等級7等）
A38: ⑦小さい家/コンパクト系 | B38: 40万-99万 | C38: 「小さな」「○○坪」サイズ明示 | D38: 小さなかわいい平屋 / シンプルおしゃれの小さく可愛い平屋 | E38: 「大きい家より自分に合った家」が今の価値観 | F38: 月1本 | G38: 「小さい=安い」ではなく「小さい=賢い」のポジショニング
A40: 伸びる家の選定基準 — 撮影する家を選ぶ時の判断軸
A41: 選定基準 | B41: 重要度 | C41: 理由 | D41: 確認方法
A42: 「かわいい」「おしゃれ」と言える外観・内装か | B42: 最重要 | C42: かわいい系が再生数1位（99万）。視覚的な第一印象がクリック率を決める | D42: 外観写真を見て「かわいい」と言えるか直感チェック
A43: 視聴者の最多層（55-64歳）に刺さるテーマがあるか | B43: 最重要 | C43: 視聴者の35.3%が55-64歳。老後/バリアフリー/コンパクト/安心がキーワード | D43: 家の特徴に老後/バリアフリー/コンパクト要素があるか
A44: タイトルで感情を動かせる特徴があるか | B44: 高 | C44: 驚き/憧れ/共感/好奇心のいずれかを刺激できないとクリックされない | D44: 1行で「おっ」と思える特徴があるか
...

Sheet YouTube投稿計画
A1: 月 | B1: 週 | C1: 投稿日 | D1: パターン | E1: 撮影対象（工務店/物件） | F1: タイトル案 | G1: サムネ案 | H1: 概要欄CTA | I1: 撮影日 | J1: 編集担当 | K1: ステータス | L1: 再生数 | M1: 備考
A2: 4月 | B2: W1 | C2: 04/01 | D2: ①かわいい系 | F2: 【タイトル案】小さくてかわいい平屋を見つけた！ | G2: かわいい外観のアップ+「小さな平屋」テキスト | H2: Web→相談/資料請求/見学会 | K2: 企画中 | M2: 概要欄にぺいほーむURL必須
A3: 4月 | B3: W1 | C3: 04/04 | D3: ③価格公開系 | F3: 【タイトル案】お値段全公開！2,000万円以下の高性能平屋 | G3: 価格大きく表示+「全公開」スタンプ | H3: Web→ローンシミュレーター | K3: 企画中 | M3: 価格への関心は全層共通
A4: 4月 | B4: W2 | C4: 04/08 | D4: ②老後安心系 | F4: 【タイトル案】60代夫婦が選んだ最高の平屋暮らし | G4: シニア夫婦+明るいリビング | H4: Web→相談 | K4: 企画中 | M4: 最多視聴者層55-64歳に直撃
A5: 4月 | B5: W2 | C5: 04/11 | D5: ④驚き系 | F5: 【タイトル案】嘘でしょ...この平屋の間取りが天才すぎる | G5: 驚き顔+間取り図チラ見せ | H5: Web→記事「間取りガイド」 | K5: 企画中 | M5: 驚きが嘘にならない家を選ぶ
A6: 4月 | B6: W3 | C6: 04/15 | D6: ⑤女性ターゲット系 | F6: 【タイトル案】大人の女性が本当に住みたい平屋はこれだ | G6: おしゃれキッチン/インテリア | H6: Web→相談 | K6: 企画中 | M6: 女性比率54%を活用
A7: 4月 | B7: W3 | C7: 04/18 | D7: ⑦コンパクト系 | F7: 【タイトル案】22坪でここまで快適！驚きのコンパクト平屋 | G7: コンパクト間取り+「22坪」大きく | H7: Web→ローンシミュレーター | K7: 企画中 | M7: 小さい家＝賢い選択のポジショニング
A8: 4月 | B8: W4 | C8: 04/22 | D8: ⑥トレンド系 | F8: 【タイトル案】2026年最も人気のある平屋の間取りベスト3 | G8: ランキング形式サムネ | H8: Web→記事 | K8: 企画中 | M8: ランキング形式は視聴時間が伸びる
A9: 4月 | B9: W4 | C9: 04/25 | D9: ⑧取材/特集 | F9: 【タイトル案】鹿児島で平屋を建てるならこの工務店（取材） | G9: 工務店代表+施工事例 | H9: Web→工務店詳細ページ | K9: 企画中 | M9: パートナー工務店の取材動画
A10: 5月
A11: 5月
A12: 5月
A13: 5月
A14: 5月
A15: 5月
A16: 5月
A17: 5月
A18: 5月
A19: 6月
A20: 6月
A21: 6月
... A27: 6月

Sheet YouTube動画トンマナ
A1: YouTube動画トンマナ — コメント分析に基づく動画構成強化ガイド
A3: コメント分析結果 — 視聴者が最も反応する要素
A4: 需要カテゴリ | B4: コメント例（実際の声） | C4: いいね数傾向 | D4: 視聴者心理 | E4: 動画構成への反映方法 | F4: 優先度
A5: ①老後・バリアフリー需要 | B5: 「高齢になると階段生活は大変です」「年を取ると二階に上がることも面倒」 | C5: 高（17-29いいね） | D5: 55-64歳が35.3%。自分の将来を重ねて見ている。「安心」「楽」が刺さる | E5: 動画冒頭で「老後も安心のポイント」に触れる。段差なし・広い廊下・手すり設置を明示的に紹介 | F5: 最重要
A6: ②コンパクト・掃除のしやすさ | B6: 「家が小さいと掃除（管理）がしやすい」「コンパクトな家いいですね」 | C6: 高（17いいね） | D6: 管理の手間を減らしたい。大きすぎる家は不要。「ちょうどいいサイズ」への共感 | E6: 「○○坪でこの広さ」と具体的に伝える。掃除・管理のしやすさを言及するコーナーを設ける | F6: 最重要
A7: ③キッチン・パントリー・収納 | B7: 「パントリーも広い」「キッチンの食器棚が引き戸。これ良い」「収納もよく考えられている」「ゴミ箱の置場所があるのもよい」 | C7: 高（24いいね） | D7: 女性54%の視聴者が最も注目する箇所。生活の具体的な使い勝手を想像している | E7: キッチン・パントリーは必ず30秒以上紹介。引き出し・棚を開けて見せる。「ゴミ箱置場」等の細部まで触れる | F7: 最重要
A8: ④価格・コスパ | B8: 「平屋建てって長い目で見るとコスパ高くて1番良い」「外壁傷んでも足場かけないでやれるから100万前後安く」「価格も優しい！」 | C8: 中-高 | D8: 価格情報への飢餓感が強い。メンテナンスコストまで含めたトータルコストへの関心 | E8: 価格は動画内で必ず触れる。坪単価・総額に加え「メンテナンスコストが安い理由」を説明する | F8: 高
A9: ⑤動線（玄関→キッチン等） | B9: 「玄関からキッチンが近いのは食材など重い荷物をすぐ置ける」「キッチンのすぐ横にダイニングテーブルがないのがいい」 | C9: 中（8-15いいね） | D9: 実際の暮らしを想像しながら見ている。「買い物帰り→荷物置き」の具体シーンが刺さる | E9: 間取り紹介時に「生活動線」を意識した説明を入れる。「買い物帰りはここから→ここ」と生活シーンで語る | F9: 高
A10: ⑥お風呂・水回り | B10: 「お風呂が広い」「トイレいいですね」 | C10: 中（3-24いいね） | D10: 水回りの快適さは毎日の生活品質に直結。特にシニア層は広い浴室を重視 | E10: お風呂は広さ・メーカー・サイズを明示。ユニットバスのグレードを説明 | F10: 中
A11: ⑦採光・明るさ | B11: 「最高な採光が最高でした」「採光がたっぷりで白が基調でかなり好み」 | C11: 中 | D11: 明るい家＝幸せな暮らしのイメージ。写真映えにも直結 | E11: 撮影時に自然光を活かす。「この窓からこう光が入る」と採光設計を説明 | F11: 中
A12: ⑧女性設計士・女性目線 | B12: 「女性設計士さん営業さんは男性多い業界で貴重」「男の私でも好感度高い」 | C12: 高（29いいね） | D12: 女性目線の設計への信頼感。男性視聴者も女性目線の家を肯定的に評価 | E12: 設計者が女性の場合は動画内で紹介。「女性目線のこだわり」をテーマに | F12: 中
A13: ⑨説明のおもしろさ・ナレーション | B13: 「部屋の中の説明の言葉が面白くって笑ってしまう」「楽しかったやないかい」「おもしろかったです」 | C13: 高（7-22いいね） | D13: エンタメ性が視聴維持率を上げる。「楽しい」と感じるとチャンネル登録率UP | E13: ナレーションにユーモアを入れる。固い専門用語だけでなく、感情的な表現を交える | F13: 高
A14: ⑩2人暮らし・おひとり様需要 | B14: 「2人暮らしならこの広さ充分」「おひとり様の理想を叶えた」 | C14: 中（8いいね） | D14: シニア夫婦・おひとり様需要が拡大。コンパクト平屋の需要と一致 | E14: 「夫婦2人暮らし」「おひとり様向け」を明示的にタイトルやテーマに含める | F14: 高
A15: ⑪地方在住者の共感 | B15: 「大阪は30坪で広い」「愛知県でも依頼できるのかな？」 | C15: 中 | D15: 他地域の視聴者も多く、自分の地域との比較で見ている。依頼可能エリアへの関心 | E15: 動画の概要欄に対応エリア情報を記載。「この工務店は○○エリア対応」と明示 | F15: 低
A17: 動画トンマナガイドライン — コメント需要を反映した構成ルール
A18: 項目 | B18: 推奨ルール | C18: 理由（コメント根拠） | D18: 具体例
A19: オープニング（0-30秒） | B19: 家の外観＋「この家のすごいところは○○」と1つだけフック | C19: 視聴者は最初の30秒で離脱判断する。コメントで「かわいい」「すごい」が多い動画ほど再生数が高い | D19: 「今回の平屋は25坪でめちゃくちゃかわいい家です。しかも価格が驚き…」
A20: 価格紹介（1-2分目） | B20: 総額・坪単価・メンテナンスコストのメリットを必ず触れる | C20: 「コスパ高い」「価格も優しい」等のコメントが多い。価格情報への需要が極めて高い | D20: 「総額1,980万円、坪単価63万円。平屋はメンテナンスで100万円以上安くなります」
A21: キッチン紹介（3-5分目） | B21: 最低30秒以上。引き出し・パントリー・ゴミ箱置場まで見せる | C21: 「パントリーも広い」「食器棚が引き戸」「ゴミ箱の置場所がある」等のコメントが最多いいね | D21: 引き出しを実際に開ける/パントリーの中を見せる/「ここにゴミ箱が置けます」と指差し
A22: 動線説明 | B22: 生活シーンで語る（買い物帰り→荷物→キッチンの流れ） | C22: 「玄関からキッチンが近いのは荷物をすぐ置ける」等、生活シーンベースのコメントが共感を得ている | D22: 「買い物から帰ってきて、ここで靴を脱いで、3歩でキッチンです」
A23: 収納紹介 | B23: 必ず扉を開けて中を見せる。具体的なサイズ感を伝える | C23: 「収納もよく考えられている」というコメントが多い。見えない部分への関心が高い | D23: クローゼットを開けて「ここに布団が入ります」「奥行き80cmなので衣装ケースが入ります」
A24: バリアフリー言及 | B24: 段差なし・広い廊下・手すり対応を明示的に紹介 | C24: 最多視聴層が55-64歳。「高齢になると階段が大変」等のコメントが高いいね | D24: 「ここは段差がゼロです」「廊下幅は車椅子も通れる90cm」
A25: ナレーションのトーン | B25: 専門的だが親しみやすく。ユーモアを交える。感情的な表現を入れる | C25: 「説明が面白くて笑ってしまう」「楽しかった」のコメントが多い。エンタメ性が視聴維持率を上げる | D25: 「このキッチン、ちょっとヤバいです…（笑）」「ここ、僕が一番好きなポイントです」
A26: エンディング（最後1分） | B26: Webサイト誘導＋LINE誘導＋次回予告 | C26: 「依頼できるのかな？」等のコメントがある。視聴後のアクション導線が不足 | D26: 「この工務店の詳しい情報はぺいほーむのサイトで。概要欄にリンクがあります」
A27: サムネイル | B27: 外観全体＋大きなテキスト（3-5文字）＋価格or坪数 | C27: モバイル49.4%。小さい画面でも読めるサイズが必要 | D27: 外観写真＋「25坪の平屋」or「1,980万円」＋かわいいフォント
A28: 動画の長さ | B28: 10-15分が最適。8分以下だと短すぎ、20分超えると離脱増 | C28: 現在の平均18分はやや長め。「2倍速で見てます」というコメントもある | D28: 12-15分を目標。テンポよく進める。間延びする部分はカット
A30: 動画で必ず触れるべき項目チェックリスト
A31: チェック項目 | B31: 理由 | C31: 目安時間 | D31: 動画内の位置
A32: □ 外観全体ショット | B32: サムネイルにも使える。第一印象を決定 | C32: 10秒 | D32: オープニング
A33: □ 総額・坪単価 | B33: 価格情報への需要が極めて高い | C33: 30秒 | D33: 序盤1-2分
A34: □ 間取り図（テロップ） | B34: 全体像の把握。スマホ視聴者は図がないと分かりにくい | C34: 15秒 | D34: 序盤
A35: □ 玄関→キッチンの動線 | B35: 生活シーンで最もコメントが多い動線 | C35: 30秒 | D35: 中盤
A36: □ キッチン詳細（引き出し・パントリー開ける） | B36: コメント最多カテゴリ。必ず実演で見せる | C36: 60秒 | D36: 中盤
A37: □ 収納を開けて見せる | B37: 見えない部分への関心が高い | C37: 30秒 | D37: 中盤
A38: □ お風呂・トイレ（メーカー・サイズ明示） | B38: 水回りへの関心は常に高い | C38: 30秒 | D38: 中盤
A39: □ バリアフリー要素（段差なし・手すり等） | B39: 最多視聴者層（55-64歳）の最大関心事 | C39: 20秒 | D39: 随所
A40: □ 採光・窓からの景色 | B40: 「明るい家」への共感が多い | C40: 15秒 | D40: 随所
A41: □ メンテナンスコストの優位性 | B41: 「コスパ高い」コメントの根拠を提供 | C41: 20秒 | D41: 終盤
A42: □ 工務店情報＋対応エリア | B42: 「依頼できるか？」の声に応える | C42: 15秒 | D42: 終盤
A43: □ Webサイト・LINE誘導 | B43: 視聴後のアクション導線 | C43: 10秒 | D43: エンディング

Sheet 動画企画マニュアル
A1: ルームツアー動画 選定・企画マニュアル
A3: STEP 1: 撮影する家の選定基準（スコアリング方式）
A4: 選定基準 | B4: 配点 | C4: 5点（最高） | D4: 3点（中） | E4: 1点（低） | F4: 判定メモ欄
A5: 外観の「かわいさ」「おしゃれさ」 | B5: 20点 | C5: 一目で「かわいい！」と言える。写真映え◎ | D5: 普通に綺麗。特徴的ではない | E5: 外観に特徴がない/古い印象
A6: 視聴者層へのフィット（55-64歳） | B6: 20点 | C6: 老後安心/バリアフリー/コンパクトの要素が複数ある | D6: 要素が1つある | E6: 若者向け/ファミリー向けのみ
A7: タイトルの感情フック | B7: 15点 | C7: 「嘘だろ」「天才的」「かわいすぎる」等が自然に出る | D7: 特徴はあるが驚きが弱い | E7: タイトルに困る。特徴が言えない
A8: 価格帯（1,500-3,000万） | B8: 15点 | C8: 1,500-2,500万円（最適レンジ） | D8: 2,500-3,500万円 | E8: 3,500万円超 or 1,500万円未満
A9: 坪数（20-32坪） | B9: 10点 | C9: 20-28坪（コンパクト系） | D9: 28-35坪 | E9: 35坪超
A10: キッチン・収納の特徴 | B10: 10点 | C10: パントリー/アイランドキッチン/特徴的な収納あり | D10: 標準的なキッチン | E10: 特筆すべき点なし
A11: 間取りの語れるポイント | B11: 5点 | C11: 回遊動線/中庭/家事動線等が複数ある | D11: 1つある | E11: 特になし
A12: 工務店との関係・撮影しやすさ | B12: 5点 | C12: 既存パートナー/取材歓迎 | D12: 要交渉 | E12: 初回接触/ハードル高
A14: 合計スコア判定基準
A15: 80-100点 | B15: 即撮影。最優先で企画する
A16: 60-79点 | B16: 撮影推奨。タイトルの工夫で伸びる可能性あり
A17: 40-59点 | B17: 保留。他に候補がなければ撮影
A18: 39点以下 | B18: 見送り。視聴者ニーズとの乖離が大きい
A20: STEP 2: タイトル作成の公式
A21: 公式パターン | B21: 構造 | C21: 実績タイトル例 | D21: 再生数
A22: 感情形容詞 + サイズ + 平屋 | B22: 「○○な」＋「小さな/コンパクトな」＋「平屋」 | C22: 小さなかわいい平屋 | D22: 99万
A23: ターゲット明示 + 安心/理想 + 平屋 | B23: 「○○向け/○○のための」＋「安心/理想」＋「平屋」 | C23: 老後も安心して過ごせる最先端の平屋 | D23: 91万
A24: 完璧/究極 + 特徴 + 平屋 | B24: 「完璧な/究極の」＋「間取り/デザイン」＋「平屋」 | C24: 完璧な間取りのお洒落で超かわいい平屋 | D24: 78万
A25: 驚き表現 + 常識を覆す + 平屋 | B25: 「嘘だろ/えっ/ヤバすぎ」＋「これが平屋？」 | C25: 嘘だろ...これが平屋はヤバすぎる！ | D25: 47万
A26: 価格公開 + サイズ + 特徴 + 平屋 | B26: 「お値段大公開」＋「○○坪」＋「高性能/かわいい」 | C26: お値段大公開！！20坪の小さな高性能平屋 | D26: 59万
A27: ターゲット + 特徴 + 平屋 | B27: 「女性/夫婦/おひとり様」＋「似合う/理想」＋「平屋」 | C27: 完全に大人の女性に似合う平屋！ | D27: 50万
A29: STEP 3: 撮影当日チェックリスト
A30: フェーズ | B30: チェック項目 | C30: 備考
A31: 撮影前 | B31: □ 外観3方向から撮影（正面・斜め・引き） | C31: サムネイル候補を複数確保
B32: □ 間取り図を入手/撮影 | C32: テロップ用
B33: □ 工務店の担当者に確認：価格・坪数・性能値 | C33: 動画内で正確に伝えるため
B34: □ 天気・時間帯確認（自然光が入る時間帯に撮影） | C34: 採光が動画の印象を大きく左右する
A35: 撮影中 | B35: □ 玄関から入って生活動線に沿って撮影 | C35: 視聴者が「住んでいる感覚」を得られるように
B36: □ キッチン：引き出し・パントリー・ゴミ箱置場を開けて撮影 | C36: コメント需要No.1
B37: □ 収納：クローゼット・押入れ・シューズクロークを開ける | C37: 見えない部分への関心が高い
B38: □ お風呂：メーカー名・サイズを映す
B39: □ 段差・廊下幅・手すりのバリアフリー要素を撮影 | C39: 最多視聴者層のニーズ
B40: □ 窓からの景色・採光を撮影 | C40: 「明るい家」への共感
B41: □ 外構・庭・駐車場も撮影 | C41: 全体像の把握
A42: 撮影後 | B42: □ 工務店にサムネイル・タイトル案を確認 | C42: 掲載許可の確認
B43: □ 概要欄テンプレートにWebサイトURL・LINE・工務店情報を記入 | C43: 送客導線の確保
A45: STEP 4: 編集・公開チェックリスト
...

Sheet 営業提案フロー
A1: STEP | B1: フェーズ名 | C1: 目的 | D1: 具体的アクション | E1: 使用ツール/資料 | F1: 判断基準（次STEPへ進む条件） | G1: 想定期間 | H1: トークスクリプト要点 | I1: 注意点
A2: 1 | B2: リスト作成 | C2: アプローチ先を選定 | D2: ①Web検索で九州の工務店リスト作成 ②平屋施工実績がありそうな会社を選別 ③メールアドレス・問い合わせフォームURL取得 | E2: 工務店ターゲットリスト（スプシ） | F2: 50社リスト完成 | G2: 1週間 | H2: N/A | I2: 平屋実績が確認できる会社を優先。大手ハウスメーカーは対象外
A3: 2 | B3: 初回アプローチ | C3: 接点を作る | D3: ①テンプレートAをカスタマイズ ②工務店の特徴・強みを調べて本文に反映 ③メールフォームまたはメールで送信 ④送信記録をスプシに記入 | E3: テンプレートA（初回提案）/メール営業管理シート | F3: メール送信完了 | G3: 月5社ペース | H3: 「貴社の○○に注目し」→具体的な特徴を入れる | I3: 一斉送信禁止。必ず1社ずつカスタマイズ
A4: 3 | B4: フォローアップ | C4: 返信を促す | D4: ①7日後に未返信の場合テンプレートBを送信 ②最新の動画実績を1つ追加 ③2回目も未返信なら1ヶ月後にテンプレートCで再アプローチ | E4: テンプレートB（フォロー） | F4: 返信あり | G4: 送信後7日 | H4: 最新動画の再生数を具体的に入れる | I4: 2回フォローして反応なしなら3ヶ月後に再アプローチ
A5: 4 | B5: オンライン商談 | C5: ニーズ把握 | D5: ①15分のオンラインミーティング実施 ②工務店の課題をヒアリング ③ぺいほーむの概要を提案書で説明 ④トライアルの打診 | E5: 提案書（PPTX）/Zoom or Google Meet | F5: 商談実施 | G5: アポから1週間以内 | H5: 「現在の集客で困っていることは？」「反響単価はいくら？」 | I5: 聞く7割、話す3割。課題を先に引き出す
A6: 5 | B6: 提案書送付 | C6: 検討材料を提供 | D6: ①商談内容を踏まえてプラン推奨 ②テンプレートDで提案書PDF送付 ③1週間後にフォロー連絡 | E6: テンプレートD（事例共有）/提案書PDF | F6: 提案書送付完了 | G6: 商談後2日以内 | H6: 「先日のお話を踏まえ、○○プランが最適と考えます」 | I6: 鮮度が命。商談後2日以内に送る
A7: 6 | B7: トライアル案内 | C7: 行動ハードルを下げる | D7: ①テンプレートEで無料トライアルの詳細送付 ②撮影日程の候補を3つ提示 ③「参加希望」の返信をもらう | E7: テンプレートE（トライアル） | F7: トライアル参加表明 | G7: 提案後1週間 | H7: 「まずは1ヶ月無料で効果を実感してください」 | I7: 無料であること・継続義務なしを強調
A8: 7 | B8: トライアル実施 | C8: 価値を体感してもらう | D8: ①掲載情報ヒアリング（オンライン30分） ②ルームツアー撮影 ③動画公開+Webページ掲載 ④反響をお届け | E8: ヒアリングシート/撮影機材/掲載基準書 | F8: トライアル完了 | G8: 1ヶ月 | H8: 撮影時：「視聴者はキッチン・収納に最も関心があります」 | I8: 撮影品質が全て。最高の動画を撮る
A9: 8 | B9: レポート共有 | C9: 成果を示す | D9: ①1ヶ月間のレポート作成（動画再生数・Web閲覧数・反響数） ②対面またはオンラインで共有 ③有料プランの提案 | E9: 月次レポートテンプレート | F9: レポート共有完了 | G9: トライアル終了後3日以内 | H9: 「1ヶ月で○件の反響がありました。業界平均の単価は○円ですが…」 | I9: 数字で語る。感覚的な説明はNG
A10: 9 | B10: 契約締結 | C10: 有料パートナー化 | D10: ①推奨プランの提案 ②契約書の説明・締結 ③初回請求 ④運用開始 | E10: 契約書テンプレート/請求書 | F10: 契約書締結 | G10: レポート後1-2週間 | H10: 「スタンダードプランが最もバランスが良いと考えます」 | I10: 無理に高いプランを押さない。信頼関係を優先
A11: 10 | B11: 運用・フォロー | C11: 長期パートナーシップ | D11: ①月次レポート送付 ②四半期ごとの振り返りミーティング ③追加撮影・コンテンツ制作 ④紹介獲得 | E11: 月次レポート/振り返りアジェンダ | F11: 継続契約 | G11: 継続 | H11: 「今月は○件の反響がありました。来月は○○を改善しましょう」 | I11: 退会の兆候を見逃さない。課題があれば先手で対応

Sheet ペルソナカード
A1: 項目 | B1: ペルソナ1: セカンドライフ田中さん | C1: ペルソナ2: 建て替え鈴木さん | D1: ペルソナ3: 初回取得 山田さん
A2: 名前（仮） | B2: 田中 洋子 | C2: 鈴木 恵美 | D2: 山田 翔太・美咲
A3: 年齢 | B3: 62歳 | C3: 52歳 | D3: 38歳
A4: 性別 | B4: 女性 | C4: 女性 | D4: 夫婦（妻が主導）
A5: 家族構成 | B5: 夫婦2人（子供は独立） | C5: 夫婦＋高校生の子供1人 | D5: 夫婦＋幼児2人（3歳・1歳）
A6: 居住地 | B6: 鹿児島市 | C6: 福岡市近郊 | D6: 鹿児島市近郊
A7: 現在の住まい | B7: 築30年の2階建て戸建て | C7: 築25年の2階建て戸建て | D7: 賃貸マンション（2LDK）
A8: 年収 | B8: 年金＋貯蓄（世帯600万円） | C8: 世帯800万円 | D8: 世帯550万円
A9: 予算 | B9: 2,000〜2,800万円 | C9: 2,500〜3,500万円 | D9: 1,800〜2,500万円
A10: 土地 | B10: あり（現在の土地に建て替え） | C10: あり（現在の土地に建て替え） | D10: なし（土地探しから）
A11: 平屋を選ぶ理由 | B11: 老後の階段が不安。2階は使わなくなった。コンパクトに暮らしたい | C11: 子供が独立後を見据えて。家事動線を楽にしたい。将来のバリアフリー対応 | D11: 子育て中の安全性。子供の様子が見えるワンフロア。庭で遊ばせたい
A12: 最も重視すること | B12: バリアフリー・段差なし・コンパクト・管理のしやすさ | C12: 家事動線・収納・キッチン・おしゃれなデザイン | D12: 価格・子育て動線・将来の部屋数・土地提案
... A21: 構成比（YouTube実データ） | B21: 35.3%（55-64歳）+ 21.6%（65歳以上）= 56.9% | C21: 29.1%（45-54歳） | D21: 10.9%（35-44歳）

Sheet 月次P_L
A1: 項目 | B1: 4月 | C1: 5月 | D1: 6月 | E1: 7月 | F1: 8月 | G1: 9月 | H1: Q2合計 | I1: 備考
A2: 【売上】
A3: YouTube広告収益 | H3: =SUM(B3:G3) | I3: YouTubeアナリティクスから
A4: 反響課金（リード送客） | H4: =SUM(B4:G4) | I4: リード数×単価
A5: 掲載料（月額パートナー） | H5: =SUM(B5:G5) | I5: パートナー数×月額
A6: 動画撮影費 | H6: =SUM(B6:G6) | I6: 撮影本数×単価
A7: SNS運用代行 | H7: =SUM(B7:G7) | I7: 契約社数×月額
A8: その他売上 | H8: =SUM(B8:G8)
A9: 売上合計 | B9: =SUM(B3:B8) | C9: =SUM(C3:C8) | D9: =SUM(D3:D8) | E9: =SUM(E3:E8) | F9: =SUM(F3:F8) | G9: =SUM(G3:G8) | H9: =SUM(B9:G9)
A11: 【経費】
A12: 撮影・制作費 | H12: =SUM(B12:G12) | I12: 外注・機材・交通費
A13: ツール費（Supabase/Vercel等） | H13: =SUM(B13:G13) | I13: 月額固定
A14: 広告費（YouTube/SNS） | H14: =SUM(B14:G14)
A15: 人件費 | H15: =SUM(B15:G15)
A16: 通信費・その他 | H16: =SUM(B16:G16)
A17: 経費合計 | B17: =SUM(B12:B16) | C17: =SUM(C12:C16) | D17: =SUM(D12:D16) | E17: =SUM(E12:E16) | F17: =SUM(F12:F16) | G17: =SUM(G12:G16) | H17: =SUM(B17:G17)
A19: 【損益】
A20: 営業利益 | B20: =B9-B17 | C20: =C9-C17 | D20: =D9-D17 | E20: =E9-E17 | F20: =F9-F17 | G20: =G9-G17 | H20: =H9-H17
A21: 累計損益 | B21: =B20 | C21: =B21+C20 | D21: =C21+D20 | E21: =D21+E20 | F21: =E21+F20 | G21: =F21+G20 | H21: =G21

Sheet 週次KPIレポート
A1: ぺいほーむ 週次KPIレポート
A2: 対象期間: | B2: 2026/○/○ 〜 2026/○/○
A4: KPI | B4: 今週 | C4: 先週 | D4: 増減 | E4: 目標 | F4: 達成率 | G4: メモ
A5: WebサイトPV | D5: =B5-C5 | F5: =IF(E5=0,"",B5/E5)
A6: YouTube週間視聴回数 | D6: =B6-C6 | F6: =IF(E6=0,"",B6/E6)
A7: AI相談開始数 | D7: =B7-C7 | F7: =IF(E7=0,"",B7/E7)
A8: 新規リード数 | D8: =B8-C8 | F8: =IF(E8=0,"",B8/E8)
A9: 相談フォーム送信数 | D9: =B9-C9
A10: 資料請求数 | D10: =B10-C10
A11: 見学会予約数 | D11: =B11-C11
A12: お気に入り追加数 | D12: =B12-C12
A13: パートナー工務店数 | D13: =B13-C13
A14: メール営業 送信数 | D14: =B14-C14
A15: メール営業 返信数 | D15: =B15-C15
A17: 今週のアクション振り返り
A18: □
A19: □
A20: □
A22: 来週のアクション
A23: □
A24: □
A25: □

Sheet コンテンツカレンダー
A1: 月 | B1: 週 | C1: 種別 | D1: タイトル/テーマ | E1: ターゲットペルソナ | F1: SEOキーワード | G1: 担当 | H1: ステータス | I1: 公開日 | J1: URL | K1: 備考
A2: 4月 | B2: W1 | C2: YouTube動画 | D2: 小さくてかわいい平屋（①かわいい系） | E2: ペルソナ1+2 | F2: 平屋 かわいい | G2: コンテンツ | H2: 企画中
A3: 4月 | B3: W1 | C3: SEO記事 | D3: 鹿児島で平屋を建てる費用と相場【2026年最新】 | E3: ペルソナ1 | F3: 平屋 鹿児島 費用 | G3: コンテンツ | H3: 企画中 | K3: T-11対応
A4: 4月 | B4: W2 | C4: YouTube動画 | D4: 60代夫婦が選んだ老後安心の平屋（②老後系） | E4: ペルソナ1 | F4: 平屋 老後 バリアフリー | G4: コンテンツ | H4: 企画中
A5: 4月 | B5: W2 | C5: SEO記事 | D5: 平屋の間取り3LDK｜25坪でも広く感じる設計のコツ | E5: ペルソナ2 | F5: 平屋 間取り 3LDK | G5: コンテンツ | H5: 企画中
A6: 4月 | B6: W3 | C6: YouTube動画 | D6: お値段全公開！2,000万円以下の高性能平屋（③価格系） | E6: ペルソナ3 | F6: 平屋 価格 2000万 | G6: コンテンツ | H6: 企画中
A7: 4月 | B7: W3 | C7: ニュース | D7: 2026年度の住宅補助金・減税制度まとめ | E7: 全ペルソナ | F7: 住宅 補助金 2026 | G7: コンテンツ | H7: 企画中
A8: 4月 | B8: W4 | C8: YouTube動画 | D8: 鹿児島の注目工務店取材（⑧取材系） | E8: 全ペルソナ | F8: 鹿児島 工務店 平屋 | G8: コンテンツ | H8: 企画中 | K8: パートナー工務店
A9: 4月 | B9: W4 | C9: SEO記事 | D9: 平屋と2階建てどっちがいい？メリット・デメリット比較 | E9: ペルソナ2+3 | F9: 平屋 2階建て 比較 | G9: コンテンツ | H9: 企画中

Sheet YouTube概要欄テンプレート
A1: セクション | B1: テンプレート文面 | C1: カスタマイズ箇所
A2: 冒頭（動画説明） | B2: 【ルームツアー】○○な平屋 鹿児島県にあります○○工務店さんの平屋でございました♪(´▽｀) ■ この家のポイント ・○○（特徴1） ・○○（特徴2） ・○○（特徴3） ■ スペック 間取り：○LDK / 延床面積：○坪 / 価格帯：○万円台 断熱等級：○ / 耐震等級：○ | C2: ○○部分を撮影物件に合わせて変更
A3: ぺいほーむ紹介＋CTA | B3: ━━━━━━━━━━━━━━━━━━ ▼ 平屋の家づくり、無料で相談できます ━━━━━━━━━━━━━━━━━━ ぺいほーむでは、平屋を検討中の方に ✅ 無料相談（信頼できる工務店をご紹介） ✅ 資料請求（複数社のカタログを一括） ✅ 見学会予約（完成見学会の情報をお届け） をご提供しています。 ▶ 無料で相談する https://payhome-media.com/consultation ▶ 資料請求はこちら https://payhome-media.com/catalog ▶ AIに平屋のことを聞いてみる https://payhome-media.com（チャットボットが24時間対応） | C3: URLは固定。変更不要
A4: LINE・SNS導線 | B4: ━━━━━━━━━━━━━━━━━━ ▼ ぺいほーむ公式LINE ━━━━━━━━━━━━━━━━━━ 最新の見学会情報やお得な情報をお届け！ https://line.me/R/ti/p/@253gzmoh ▼ Instagram https://www.instagram.com/pei_home/ ▼ ぺいほーむ公式サイト https://payhome-media.com | C4: SNSアカウントURL確認
A5: 工務店情報 | B5: ━━━━━━━━━━━━━━━━━━ ▼ 今回紹介した工務店 ━━━━━━━━━━━━━━━━━━ ○○工務店 所在地：鹿児島県○○市○○ 得意分野：平屋 / ○○ / ○○ Web：https://xxxxx TEL：xxx-xxxx-xxxx ▶ この工務店について詳しく見る https://payhome-media.com/builders/○○ | C5: 工務店名・URL・電話番号を撮影先に合わせて変更
A6: ハッシュタグ | B6: #平屋 #ルームツアー #平屋ルームツアー #平屋間取り #平屋内見 #鹿児島 #不動産 #鹿児島ハウスメーカー #鹿児島平屋 #平屋新築 #平屋注文住宅 #マイホーム #注文住宅 #家づくり #ぺいほーむ | C6: 地域名を撮影地に合わせて追加

Sheet 月次レビュー
A1: ぺいほーむ 月次レビュー会議アジェンダ
A2: 開催日: | C2: 参加者:
A4: 時間 | B4: 議題 | C4: 内容 | D4: 担当 | E4: 資料 | F4: 決定事項（会議中に記入）
A5: 5分 | B5: 先月の振り返り | C5: 先月のアクション実施状況の確認 | D5: 全員 | E5: 前回議事録
A6: 10分 | B6: KPIレビュー | C6: 月次KPI実績と目標比較。傾向分析 | D6: PM | E6: KPI一覧シート
A7: 10分 | B7: 営業進捗 | C7: パートナー営業の進捗。新規アプローチ結果。パイプライン状況 | D7: 営業 | E7: メール営業管理シート
A8: 10分 | B8: コンテンツ進捗 | C8: 動画・記事の制作状況。再生数・PV。コンテンツカレンダーの進捗 | D8: コンテンツ | E8: コンテンツカレンダー
A9: 10分 | B9: 掲載品質 | C9: 監査の進捗。リライト状況。工務店情報の更新状況 | D9: コンテンツ | E9: 掲載内容監査シート
A10: 10分 | B10: 来月の計画 | C10: 来月の優先Todo確認。目標設定。リソース配分 | D10: 経営 | E10: ガントチャート
A11: 5分 | B11: 課題・懸念事項 | C11: 解決が必要な問題の共有と対応方針の決定 | D11: 全員

Sheet データ活用ロードマップ
A1: 四半期 | B1: テーマ | C1: 取得するデータ | D1: 活用方法 | E1: 事業側で決めること | F1: エンジニアに依頼すること | G1: 成果イメージ
A2: Q2 2026 (4-6月) | B2: データを貯める | C2: ページ閲覧/動画視聴/チャットログ/お気に入り/リード流入元 | D2: 月次レポートで傾向を把握。「どの動画からCVが多いか」を分析 | E2: KPIの優先順位/レポートの形式/確認頻度 | F2: GA4カスタムイベント設定/レポート自動化 | G2: 月次データレポート第1号
A3: Q3 2026 (7-9月) | B3: データを使い始める | C3: ユーザープロフィール/チャット意向抽出/閲覧傾向 | D3: AIチャットの回答にデータを反映。「この人に合いそうな工務店」の推薦ロジック初期版 | E3: 推薦の基準（何を重視するか）/工務店の構造化データ入力 | F3: 推薦ロジック実装/意向抽出API | G3: AI推薦初期版のテスト
A4: Q4 2026 (10-12月) | B4: データで提案する | C4: 意向データ付きリード/行動スコアリング/成約データ | D4: 工務店に「この人は○○に関心があり、温度感は高い」と伝える。商談前要約の初期版 | E4: リードの価格設定（データ付きリード=高単価）/工務店へのレポート内容 | F4: 商談前要約生成/スコアリングUI | G4: 意向データ付きリードの初回提供
A5: 2027年 Q1以降 | B5: AIが進化する | C5: 全データの統合分析/成約パターン/next best action | D5: AI住宅コンシェルジュ本格稼働。営業支援SaaSの初期版 | E5: SaaS化の価格/ターゲット/営業戦略 | F5: AIコンシェルジュ高度化/SaaS UI | G5: AI営業支援の初期リリース

Sheet 請求テンプレート
A1: 請求書
A3: 請求先: | B3: ○○工務店 御中 | E3: 株式会社wazeka
A4: 請求日: | B4: 2026年○月○日 | E4: 鹿児島県鹿児島市○○
A5: お支払期限: | B5: 2026年○月末日 | E5: TEL: xxx-xxxx-xxxx
E6: 登録番号: T○○○○○○○○○○○○○
A8: No. | B8: 品目 | C8: 数量 | D8: 単価 | E8: 金額 | F8: 備考
A9: 1 | B9: プラットフォーム掲載料（○月分） | C9: 1 | E9: =C9*D9 | F9: スタンダードプラン
A10: 2 | B10: ルームツアー動画撮影・制作 | C10: 0 | E10: =C10*D10
A11: 3 | B11: リード送客費（○件×○円） | C11: 0 | E11: =C11*D11
D12: 小計 | E12: =SUM(E9:E11)
D13: 消費税（10%） | E13: =E12*0.1
D14: 合計 | E14: =E12+E13
A16: お振込先
A17: ○○銀行 ○○支店 普通 ○○○○○○○ カ）ワゼカ

Sheet 比較コンテンツ構成案
A1: 記事No. | B1: タイトル案 | C1: ターゲット | D1: 構成（H2見出し案） | E1: SEOキーワード | F1: 優先度 | G1: ステータス
A2: 比較-01 | B2: 【2026年版】鹿児島で平屋が得意な工務店10選｜特徴・価格帯・口コミを比較 | C2: ペルソナ1+2 | D2: H2: 鹿児島の平屋市場の現状 / H2: 工務店選びの5つのポイント / H2: 工務店10社の比較表 / H2: タイプ別おすすめ（コスパ重視/デザイン重視/性能重視） / H2: まとめ | E2: 鹿児島 工務店 平屋 おすすめ | F2: 高 | G2: 企画中
A3: 比較-02 | B3: 平屋vs2階建て｜メリット・デメリットを徹底比較【コスト・間取り・老後】 | C3: ペルソナ2+3 | D3: H2: 平屋のメリット5つ / H2: 平屋のデメリット3つ / H2: 2階建てとのコスト比較 / H2: 老後を見据えたらどっち？ / H2: こんな人は平屋がおすすめ | E3: 平屋 2階建て 比較 メリット | F3: 高 | G3: 企画中
A4: 比較-03 | B4: 平屋の断熱等級4・5・6・7の違い｜鹿児島で必要なレベルはどれ？ | C4: ペルソナ1+2 | D4: H2: 断熱等級とは / H2: 等級4〜7の違い / H2: 鹿児島の気候と断熱 / H2: UA値の目安 / H2: 断熱等級別の費用差 / H2: おすすめの等級 | E4: 断熱等級 平屋 鹿児島 UA値 | F4: 中 | G4: 企画中
