Workbook

Sheet ダッシュボード
A1: ぺいほーむ 営業ダッシュボード
A3: PF掲載 申込社数 | B3: マーケ支援 契約社数 | C3: 今月売上 | D3: 累計売上 | E3: テレアポ 累計 | F3: 商談数 | G3: タスク 完了率
A4: =COUNTIFS('テレアポ管理（鹿児島）'!T2:T100,"申込済み") | B4: =COUNTIFS('テレアポ管理（全国）'!U2:U100,"契約済み") | E4: =COUNTA('テレアポ管理（鹿児島）'!K2:K100)+COUNTA('テレアポ管理（全国）'!K2:K100) | F4: =COUNTIFS('テレアポ管理（鹿児島）'!T2:T100,"商談済み")+COUNTIFS('テレアポ管理（鹿児島）'!T2:T100,"申込済み")+COUNTIFS('テレアポ管理（全国）'!U2:U100,"商談済み")+COUNTIFS('テレアポ管理（全国）'!U2:U100,"契約済み") | G4: =IFERROR(COUNTIFS(タスク管理!I2:I100,"完了")/COUNTA(タスク管理!A2:A100),0)
A5: 目標: 20社 | B5: 目標: 3社
A7: 現在のフェーズ
A8: 4月 | C8: 5/1 | E8: 5〜7月 | G8: 8/1 | I8: 8〜12月
A9: 営業準備 テレアポ | C9: リリース | E9: フリープラン データ蓄積 | G9: 有料移行 | I9: 有料運用 クロスセル
A11: 直近のアクション
A12: 時期 | B12: アクション | C12: 優先度
A13: 今週 | B13: テレアポリスト50社作成＋営業資料最終確認＋ロープレ実施 | C13: 高
A14: 来週 | B14: テレアポ開始（鹿児島80件＋全国40件） | C14: 高
A15: 4/14 | B15: フリープラン申込クロージング（期限4/20） | C15: 高
A16: 4/21 | B16: 掲載ページ作成開始 | C16: 中
A17: 5/1 | B17: プラットフォームリリース | C17: 高

Sheet 戦略概要
A1: ぺいほーむ 事業戦略概要
A3: 事業の2本柱
A4: プラットフォーム掲載 | B4: 鹿児島→九州。フリープラン→有料化。長期の事業基盤。データ×AI進化
A5: マーケティング支援 | B5: 全国対応。動画・SNS運用代行。短期のキャッシュエンジン＋全国の工務店接点
A7: フリープラン設計思想
A8: なぜ無料か | B8: リリース直後はユーザーが少ない。少ないうちからお金をいただくのは筋が通らない。最初の3ヶ月は価値を証明する期間
A9: 3ヶ月後 | B9: データレポートを提示。価値があれば有料化、なければやめてOK
A10: 有料化基準 | B10: 資料請求or見学会予約1件以上 or 月間閲覧100回以上
A12: 競争優位性
A13: YouTube | B13: 登録者42,841人 / 動画257本 / 月間15万回再生 / 九州No.1平屋専門ch
A14: ターゲット純度 | B14: 視聴者の100%が平屋検討者。SUUMOは全ジャンル混在
A15: 制作コスト | B15: 257本の実績でオペレーション確立。1本あたりコストが圧倒的に低い
A16: 反響単価 | B16: 目標1〜3万円。SUUMO平均5〜15万円の1/3〜1/5
A18: 収益シミュレーション（標準シナリオ）
A19: 月 | B19: PF掲載売上 | C19: マーケ支援売上 | D19: 月間合計 | E19: 累計
A20: 5月 | B20: 0 | C20: 240000 | D20: =B20+C20 | E20: =D20
A21: 6月 | B21: 0 | C21: 360000 | D21: =B21+C21 | E21: =E20+D21
A22: 7月 | B22: 0 | C22: 480000 | D22: =B22+C22 | E22: =E21+D22
A23: 8月 | B23: 150000 | C23: 560000 | D23: =B23+C23 | E23: =E22+D23
A24: 9月 | B24: 200000 | C24: 640000 | D24: =B24+C24 | E24: =E23+D24
A25: 10月 | B25: 250000 | C25: 720000 | D25: =B25+C25 | E25: =E24+D25
A26: 11月 | B26: 280000 | C26: 800000 | D26: =B26+C26 | E26: =E25+D26
A27: 12月 | B27: 320000 | C27: 880000 | D27: =B27+C27 | E27: =E26+D27

Sheet 料金プラン
A1: プラットフォーム掲載プラン
A3: プラン名 | B3: 月額 | C3: 資料請求 | D3: 見学会来場 | E3: 住宅契約 | F3: YouTube概要欄 | G3: 上位表示 | H3: おすすめ対象
A4: フリープラン | B4: 0円 | C4: 0円 | D4: 0円 | E4: 0円 | F4: ❌ | G4: ❌ | H4: 全社（5〜7月）
A5: 成果報酬 | B5: 0円 | C5: 8,000円/件 | D5: 80,000円/件 | E5: 4% | F5: ❌ | G5: ❌ | H5: 反響月2件以下
A6: 掲載ベーシック | B6: 30,000円 | C6: 5,000円/件 | D6: 50,000円/件 | E6: 3% | F6: ✅ | G6: ❌ | H6: 反響月3〜5件
A7: 掲載プロ | B7: 50,000円 | C7: 3,000円/件 | D7: 30,000円/件 | E7: 2% | F7: ✅ | G7: ✅ | H7: 反響月5件以上
A10: マーケティング支援プラン
A12: プラン名 | B12: 月額 | C12: ルームツアー | D12: ショート動画 | E12: Instagram | F12: TikTok | G12: LINE | H12: 戦略会議
A13: エントリー | B13: 80,000円 | C13: — | D13: 月4本 | E13: 週3投稿 | F13: 週2投稿 | G13: — | H13: —
A14: グロース | B14: 150,000円 | C14: 月1本 | D14: 月8本 | E14: 毎日投稿 | F14: 週3投稿 | G14: 月2配信 | H14: —
A15: プレミアム | B15: 250,000円 | C15: 月2本 | D15: 月12本 | E15: 毎日投稿 | F15: 毎日投稿 | G15: 月4配信 | H15: 月1回
A18: セット割引（掲載＋マーケ支援）
A19: 掲載プラン | B19: マーケ支援 | C19: 個別合計 | D19: セット価格 | E19: 割引額
A20: 掲載ベーシック | B20: エントリー | C20: 11万円 | D20: 10万円 | E20: ▲1万円
A21: 掲載ベーシック | B21: グロース | C21: 18万円 | D21: 16万円 | E21: ▲2万円
A22: 掲載プロ | B22: グロース | C22: 20万円 | D22: 18万円 | E22: ▲2万円
A23: 掲載プロ | B23: プレミアム | C23: 30万円 | D23: 27万円 | E23: ▲3万円
A26: 単発メニュー
A27: メニュー | B27: 価格（税別）
A28: ルームツアー動画 | B28: 150,000円/本
A29: ショート動画 | B29: 30,000円/本
A30: 見学会集客パック | B30: 100,000円/回
A31: お客様インタビュー | B31: 80,000円/本
A32: 写真撮影パック | B32: 50,000円/回
A33: LP制作 | B33: 300,000円〜

Sheet テレアポ管理（鹿児島）
A1: ID | B1: 企業名 | C1: 代表者 | D1: 担当者 | E1: 電話番号 | F1: メール | G1: エリア | H1: 従業員数 | I1: 年間施工数 | J1: 平屋実績 | K1: 1回目コール日 | L1: 1回目結果 | M1: 2回目コール日 | N1: 2回目結果 | O1: 資料送付日 | P1: 商談日 | Q1: 商談結果 | R1: 申込日 | S1: 申込プラン | T1: ステータス | U1: 担当者(自社) | V1: メモ
A2: K-001 | B2: ヤマサハウス株式会社 | C2: 森 勇清 | E2: 099-295-3911 | G2: 鹿児島市 | T2: 未コール | U2: 右田 | V2: 創業1948年 資本金9,800万円 社員193名
A3: K-002 | B3: 株式会社センチュリーハウス | C3: 加治木 百年 | E3: 099-813-0001 | G3: 鹿児島市 | T3: 未コール | U3: 右田 | V3: 設立平成9年8月 資本金1,000万円 姶良店・鹿屋店あり
A4: K-003 | B4: 株式会社七呂建設 | C4: 七呂 恵介 | E4: 099-201-3015 | G4: 鹿児島市 | T4: 未コール | U4: 右田 | V4: 創業昭和35年 資本金8,700万円 社員181名 九州各地に展開
A5: K-004 | B5: 株式会社国分ハウジング | C5: 久保 範和 | E5: 0995-45-8886 | G5: 霧島市 | T5: 未コール | U5: 右田 | V5: 創業昭和63年 資本金3,000万円 グループ社員261名
A6: K-005 | B6: 株式会社トータルハウジング | C6: 渡邊 孝太郎 | E6: 099-210-5120 | G6: 鹿児島市 | T6: 未コール | U6: 右田 | V6: 創業1991年 資本金1,000万円
A7: K-006 | B7: 株式会社NEO（NEOデザインホーム） | C7: 赤﨑 広久 | E7: 099-298-9300 | G7: 鹿児島市 | T7: 未コール | U7: 右田 | V7: 設立2005年11月 資本金5,000万円 NEOホールディングスグループ
A8: K-007 | B8: MBC開発株式会社（MBCハウス） | C8: 陶山 賢治 | E8: 099-226-7777 | G8: 鹿児島市 | T8: 未コール | U8: 右田 | V8: 創業1969年 南日本放送グループ 社員232名
A9: K-008 | B9: 丸和建設株式会社 | C9: 和田 康伸 | E9: 099-269-7600 | G9: 鹿児島市 | T9: 未コール | U9: 右田 | V9: 創業1980年10月 資本金3,000万円 社員61名
A10: K-009 | B10: 株式会社ベガハウス | C10: 大迫 学 | E10: 099-295-0788 | G10: 鹿児島市 | T10: 未コール | U10: 右田 | V10: 創業1986年5月 資本金2,500万円 社員22名
A11: K-010 | B11: 株式会社ベルハウジング | C11: 松田 英之 | E11: 099-250-0694 | G11: 鹿児島市 | T11: 未コール | U11: 右田 | V11: 創業昭和61年5月 霧島店あり
A12: K-011 | B12: 有限会社田建築工房 | C12: 田底 克也 | E12: 099-250-6347 | G12: 鹿児島市 | T12: 未コール | U12: 右田 | V12: 設立平成12年4月 資本金500万円
A13: K-012 | B13: 株式会社感動 | C13: 渡邊 孝太郎 | E13: 099-296-8881 | G13: 鹿児島市 | T13: 未コール | U13: 右田 | V13: 社員23名 姶良支店あり トータルハウジングと同代表
... A43: K-042 | B43: ロイヤルホーム株式会社 | C43: 久保 範和 | E43: 0995-73-5602 | G43: 霧島市 | T43: 未コール | U43: 右田 | V43: 資本金1億円 テクノストラクチャー工法 完成棟数ランキング4位
A44: K-043 | B44: 株式会社晃栄住宅 | C44: 仙田 次雄 | G44: 鹿児島市 | T44: 未コール | U44: 右田 | V44: 設立平成元年 資本金9,999万円 鹿児島店・北店・霧島店・川内店・姶良店
A45: K-044 | B45: 株式会社あいハウジング | C45: 川崎 廣明 | E45: 099-278-1111 | G45: 鹿児島市 | T45: 未コール | U45: 右田 | V45: 宅地造成から建売・注文住宅・アフターまで一貫体制 完成棟数ランキング12位
A46: K-045 | B46: 有限会社中央ハウス | C46: 金氣 昇造 | G46: 鹿児島市 | T46: 未コール | U46: 右田 | V46: 1987年創業 総合不動産業35年以上 完成棟数ランキング20位
A47: K-046 | B47: 株式会社シースタイル | C47: 今村 卓也 | E47: 099-295-4888 | G47: 鹿児島市 | T47: 未コール | U47: 右田 | V47: 資本金1,000万円 屋上庭園付住宅 完成棟数ランキング24位
A48: K-047 | B48: 株式会社粹家創房（イキヤソウボウ） | C48: 冨ヶ原 陽介 | E48: 099-278-7003 | G48: 鹿児島市 | T48: 未コール | U48: 右田 | V48: 2003年創業 環境配慮・無垢材の家づくり 完成棟数ランキング26位
A49: K-048 | B49: 南日本ハウス株式会社 | C49: 元山 豊二 | E49: 099-285-0888 | G49: 鹿児島市 | T49: 未コール | U49: 右田 | V49: 設立1985年 資本金5,000万円 売上高30億円 完成棟数ランキング21位
A50: K-049 | B50: 株式会社正栄ハウス | E50: 099-295-3401 | G50: 鹿児島市 | T50: 未コール | U50: 右田 | V50: 従業員40名 完成棟数ランキング28位
A51: K-050 | B51: ニューイングホーム株式会社 | C51: 豊福 久二 | E51: 0995-48-5388 | G51: 霧島市 | T51: 未コール | U51: 右田 | V51: 社員大工による家づくり 完成棟数ランキング31位
A52: K-051 | B52: 株式会社アートホーム | C52: 藤山 浩一 | E52: 099-252-8100 | G52: 鹿児島市 | T52: 未コール | U52: 右田 | V52: 設立昭和63年 資本金3,000万円 売上高16億円 完成棟数ランキング24位
A53: K-052 | B53: 株式会社継南建設 | C53: 永井 雅友 | E53: 0995-42-3207 | G53: 霧島市 | T53: 未コール | U53: 右田 | V53: 40年以上の歴史 注文住宅専門 完成棟数ランキング35位
A54: K-053 | B54: 株式会社松下孝建設 | C54: 松下 拓也 | E54: 099-267-7594 | G54: 鹿児島市 | T54: 未コール | U54: 右田 | V54: 設立昭和58年 資本金1,000万円 従業員18名 完成棟数ランキング35位
A55: K-054 | B55: 株式会社タイセイ工務店 | C55: 大田 輝美 | E55: 0996-72-0014 | G55: 阿久根市 | T55: 未コール | U55: 右田 | V55: 創業1966年 資本金2,000万円 従業員40名 年間新築30棟 完成棟数ランキング38位
A56: K-055 | B56: 株式会社ARK HOME | E56: 099-472-0052 | G56: 志布志市 | T56: 未コール | U56: 右田 | V56: 設立2016年 高気密高断熱パッシブデザイン 完成棟数ランキング39位
A57: K-056 | B57: 株式会社エヌワン開発 | C57: 宮上 辰也 | E57: 099-255-0170 | G57: 鹿児島市 | T57: 未コール | U57: 右田 | V57: 不動産業・住宅建設 完成棟数ランキング39位
A58: K-057 | B58: 株式会社グッドホームかごしま | E58: 099-220-4505 | G58: 鹿児島市 | T58: 未コール | U58: 右田 | V58: 漆喰と無垢の自然素材の家 完成棟数ランキング39位
A59: K-058 | B59: 株式会社県民住宅 | C59: 下津 春美 | E59: 099-268-5488 | G59: 鹿児島市 | T59: 未コール | U59: 右田 | V59: 創業昭和45年 資本金2,000万円 省エネ・高気密高断熱住宅 完成棟数ランキング39位
A60: K-059 | B60: 秋岡ハウジング有限会社 | C60: 馬込 久志 | E60: 0994-44-8538 | G60: 鹿屋市 | T60: 未コール | U60: 右田 | V60: 30年以上の実績 ロイヤルハウス大隅鹿屋店 完成棟数ランキング43位
A61: K-060 | B61: 株式会社さくらハウジング | C61: 古川 和人 | E61: 099-805-1121 | G61: 鹿児島市 | T61: 未コール | U61: 右田 | V61: 設立平成15年 不動産販売・住宅建築 完成棟数ランキング43位
A62: K-061 | B62: 深田建設株式会社 | G62: 奄美市 | T62: 未コール | U62: 右田 | V62: マザーホームブランド 奄美大島の住宅建築 完成棟数ランキング43位
A63: K-062 | B63: 有限会社前迫建設 | C63: 前迫 智博 | E63: 0120-76-1784 | G63: 大崎町 | T63: 未コール | U63: 右田 | V63: 創業1988年 新築・リフォーム 完成棟数ランキング48位
A64: K-063 | B64: 株式会社村岡工務店 | E64: 099-478-3636 | G64: 大崎町 | T64: 未コール | U64: 右田 | V64: 創業50余年 大隅地域密着 完成棟数ランキング48位
A65: K-064 | B65: 有限会社ヤマケン | C65: 山元 建次 | E65: 0994-43-3036 | G65: 鹿屋市 | T65: 未コール | U65: 右田 | V65: 住宅・店舗の設計施工・リフォーム 完成棟数ランキング48位
A66: K-065 | B66: 株式会社ダイワ工務店 | C66: 和田見 勝之 | E66: 099-837-3616 | G66: 鹿児島市 | T66: 未コール | U66: 右田 | V66: 創業2005年 海外デザイン住宅 新築・リフォーム・リノベーション
A67: K-066 | B67: 株式会社Sin工房 | C67: 田口 慎一 | E67: 099-268-1888 | G67: 鹿児島市 | T67: 未コール | U67: 右田 | V67: 設立平成15年 自然素材と無垢材の注文住宅
A68: K-067 | B68: 有限会社コアホーム | C68: 佐多 正人 | E68: 099-260-0635 | G68: 鹿児島市 | T68: 未コール | U68: 右田 | V68: 30年以上谷山中心 注文住宅・不動産
A69: K-068 | B69: 成尾建設株式会社 | C69: 成尾 岳次朗 | E69: 099-253-9191 | G69: 鹿児島市 | T69: 未コール | U69: 右田 | V69: 設立1971年 資本金2,025万円 R+house加盟 引渡800戸超
...

Sheet テレアポ管理（全国）
A1: ID | B1: 企業名 | C1: 代表者 | D1: 担当者 | E1: 電話番号 | F1: メール | G1: 都道府県 | H1: 従業員数 | I1: 年間施工数 | J1: 平屋実績 | K1: 1回目コール日 | L1: 1回目結果 | M1: 2回目コール日 | N1: 2回目結果 | O1: 資料送付日 | P1: 商談日 | Q1: 商談結果 | R1: 見積金額 | S1: 契約日 | T1: 契約プラン | U1: 月額 | V1: ステータス | W1: 担当者(自社) | X1: メモ

Sheet リードパイプライン
A1: ID | B1: 企業名 | C1: 商品種別 | D1: 提案プラン | E1: ステージ | F1: 確度 | G1: 見積金額 | H1: 月額想定 | I1: 担当者 | J1: 次アクション | K1: 次アクション期日 | L1: メモ | M1: 更新日

Sheet タスク管理
A1: ID | B1: カテゴリ | C1: タスク名 | D1: 詳細 | E1: 担当者 | F1: 優先度 | G1: 開始日 | H1: 期限 | I1: ステータス | J1: 進捗% | K1: 成果物 | L1: メモ
A2: S-01 | B2: 営業準備 | C2: テレアポリスト作成（鹿児島50社） | D2: 鹿児島の工務店・ハウスメーカーをリストアップ | E2: 右田 | F2: 高 | G2: 2026/3/24 | H2: 2026/3/28 | I2: 未着手 | J2: 0% | K2: リスト
A3: S-02 | B3: 営業準備 | C3: テレアポリスト作成（全国30社） | D3: 全国の平屋施工実績のある工務店をリストアップ | E3: 営業A | F3: 高 | G3: 2026/3/24 | H3: 2026/3/28 | I3: 未着手 | J3: 0% | K3: リスト
A4: S-03 | B4: 営業準備 | C4: 営業資料最終確認 | D4: 提案書・チラシ・申込書の内容最終チェック | E4: 右田 | F4: 高 | G4: 2026/3/24 | H4: 2026/3/28 | I4: 未着手 | J4: 0% | K4: 確認済み資料
A5: S-04 | B5: 営業準備 | C5: テレアポロープレ実施 | D5: スクリプトを使って練習。反論対応の確認 | E5: 全員 | F5: 高 | G5: 2026/3/27 | H5: 2026/3/28 | I5: 未着手 | J5: 0%
A6: S-05 | B6: PF掲載営業 | C6: テレアポ実施（鹿児島）Week2 | D6: 目標80件コール | E6: 右田 | F6: 高 | G6: 2026/3/31 | H6: 2026/4/4 | I6: 未着手 | J6: 0%
A7: S-06 | B7: マーケ支援営業 | C7: テレアポ実施（全国）Week2 | D7: 目標40件コール | E7: 営業A | F7: 高 | G7: 2026/3/31 | H7: 2026/4/4 | I7: 未着手 | J7: 0%
A8: S-07 | B8: PF掲載営業 | C8: 資料送付フォロー | D8: テレアポ後の資料送付＋翌日フォロー | E8: 右田 | F8: 高 | G8: 2026/4/1 | H8: 2026/4/11 | I8: 未着手 | J8: 0%
A9: S-08 | B9: PF掲載営業 | C9: テレアポ継続（鹿児島）Week3 | D9: 目標60件コール | E9: 右田 | F9: 高 | G9: 2026/4/7 | H9: 2026/4/11 | I9: 未着手 | J9: 0%
A10: S-09 | B10: マーケ支援営業 | C10: オンライン商談（マーケ支援） | D10: 目標3〜5社 | E10: 営業A | F10: 高 | G10: 2026/4/7 | H10: 2026/4/11 | I10: 未着手 | J10: 0%
A11: S-10 | B11: PF掲載営業 | C11: 訪問商談（PF掲載） | D11: 資料送付先への訪問提案 | E11: 右田 | F11: 高 | G11: 2026/4/7 | H11: 2026/4/18 | I11: 未着手 | J11: 0%
A12: S-11 | B12: PF掲載営業 | C12: フリープラン申込クロージング | D12: 期限4/20。未返答企業への最終フォロー | E12: 右田 | F12: 高 | G12: 2026/4/14 | H12: 2026/4/20 | I12: 未着手 | J12: 0%
A13: S-12 | B13: マーケ支援営業 | C13: マーケ支援 契約クロージング | D13: 見積提出済み企業への最終提案 | E13: 営業A | F13: 高 | G13: 2026/4/14 | H13: 2026/4/20 | I13: 未着手 | J13: 0%
A14: S-13 | B14: 掲載準備 | C14: 掲載ページ作成 | D14: 申込企業の紹介ページをCMSで構築 | E14: 制作 | F14: 高 | G14: 2026/4/21 | H14: 2026/4/30 | I14: 未着手 | J14: 0% | K14: 掲載ページ
A15: S-14 | B15: 運用 | C15: 初回撮影（マーケ支援） | D15: 契約企業の初回ルームツアー撮影 | E15: 制作 | F15: 高 | G15: 2026/4/21 | H15: 2026/4/30 | I15: 未着手 | J15: 0% | K15: 動画素材
A16: S-15 | B16: 掲載準備 | C16: リリース最終準備 | D16: プラットフォーム動作確認・告知準備 | E16: 全員 | F16: 高 | G16: 2026/4/28 | H16: 2026/4/30 | I16: 未着手 | J16: 0%
A17: S-16 | B17: レポート | C17: 月次レポート作成（5月分） | D17: 掲載企業へ5月の閲覧データを報告 | E17: 右田 | F17: 中 | G17: 2026/6/1 | H17: 2026/6/5 | I17: 未着手 | J17: 0% | K17: レポート
A18: S-17 | B18: レポート | C18: 月次レポート作成（6月分） | D18: 掲載企業へ6月の閲覧データを報告 | E18: 右田 | F18: 中 | G18: 2026/7/1 | H18: 2026/7/5 | I18: 未着手 | J18: 0% | K18: レポート
A19: S-18 | B19: レポート | C19: 3ヶ月総合レポート作成 | D19: 各社の3ヶ月実績を総合レポートにまとめる | E19: 右田 | F19: 高 | G19: 2026/7/15 | H19: 2026/7/20 | I19: 未着手 | J19: 0% | K19: 総合レポート
A20: S-19 | B20: PF掲載営業 | C20: 有料化提案準備 | D20: 各社に最適なプランを選定・提案資料準備 | E20: 右田 | F20: 高 | G20: 2026/7/15 | H20: 2026/7/25 | I20: 未着手 | J20: 0% | K20: 提案資料
A21: S-20 | B21: PF掲載営業 | C21: 有料化提案訪問 | D21: 全掲載企業を訪問し有料プランを提案 | E21: 右田 | F21: 高 | G21: 2026/7/20 | H21: 2026/7/31 | I21: 未着手 | J21: 0%

Sheet KPI管理
A1: 月次KPI管理
A3: 月 | B3: PF掲載社数 | C3: マーケ契約数 | D3: テレアポ数 | E3: 商談数 | F3: 新規契約 | G3: 月間PV | H3: リード数 | I3: PF売上 | J3: マーケ売上 | K3: 合計売上 | L3: 累計売上 | M3: 解約数 | N3: 解約率
B4: 20 | C4: 3 | D4: 200 | E4: 8 | F4: 5 | G4: 5000 | H4: 10 | I4: 0 | J4: 240000 | K4: 240000 | L4: 240000 | M4: 0 | N4: 0%
A5: 4月
A6: 5月
A7: 6月
A8: 7月
A9: 8月
A10: 9月
A11: 10月
A12: 11月
A13: 12月
A16: 週次KPI
A17: 週 | B17: 開始日 | C17: 終了日 | D17: コール数（鹿児島） | E17: コール数（全国） | F17: 受付突破 | G17: 資料送付 | H17: 商談 | I17: 申込/契約 | J17: 担当 | K17: メモ
A18: Week 1
A19: Week 2
A20: Week 3
A21: Week 4
A22: Week 5
A23: Week 6
A24: Week 7
A25: Week 8
A26: Week 9
A27: Week 10
A28: Week 11
A29: Week 12

Sheet 収益シミュレーション
A1: 収益シミュレーション（3シナリオ）
A3: 保守的シナリオ
A4: 月 | B4: PF掲載売上 | C4: マーケ支援売上 | D4: 月間合計 | E4: 累計
A5: 5月 | B5: 0 | C5: 160000 | D5: =B5+C5 | E5: =D5
A6: 6月 | B6: 0 | C6: 240000 | D6: =B6+C6 | E6: =E5+D6
A7: 7月 | B7: 0 | C7: 320000 | D7: =B7+C7 | E7: =E6+D7
A8: 8月 | B8: 80000 | C8: 400000 | D8: =B8+C8 | E8: =E7+D8
A9: 9月 | B9: 100000 | C9: 440000 | D9: =B9+C9 | E9: =E8+D9
A10: 10月 | B10: 120000 | C10: 480000 | D10: =B10+C10 | E10: =E9+D10
A11: 11月 | B11: 140000 | C11: 520000 | D11: =B11+C11 | E11: =E10+D11
A12: 12月 | B12: 160000 | C12: 560000 | D12: =B12+C12 | E12: =E11+D12
A13: 合計 | B13: =SUM(B5:B12) | C13: =SUM(C5:C12) | D13: =B13+C13
A16: 標準シナリオ
A17: 月 | B17: PF掲載売上 | C17: マーケ支援売上 | D17: 月間合計 | E17: 累計
A18: 5月 | B18: 0 | C18: 240000 | D18: =B18+C18 | E18: =D18
A19: 6月 | B19: 0 | C19: 360000 | D19: =B19+C19 | E19: =E18+D19
A20: 7月 | B20: 0 | C20: 480000 | D20: =B20+C20 | E20: =E19+D20
A21: 8月 | B21: 150000 | C21: 560000 | D21: =B21+C21 | E21: =E20+D21
A22: 9月 | B22: 200000 | C22: 640000 | D22: =B22+C22 | E22: =E21+D22
A23: 10月 | B23: 250000 | C23: 720000 | D23: =B23+C23 | E23: =E22+D23
A24: 11月 | B24: 280000 | C24: 800000 | D24: =B24+C24 | E24: =E23+D24
A25: 12月 | B25: 320000 | C25: 880000 | D25: =B25+C25 | E25: =E24+D25
A26: 合計 | B26: =SUM(B18:B25) | C26: =SUM(C18:C25) | D26: =B26+C26
A29: 楽観的シナリオ
A30: 月 | B30: PF掲載売上 | C30: マーケ支援売上 | D30: 月間合計 | E30: 累計
A31: 5月 | B31: 0 | C31: 320000 | D31: =B31+C31 | E31: =D31
A32: 6月 | B32: 0 | C32: 480000 | D32: =B32+C32 | E32: =E31+D32
A33: 7月 | B33: 0 | C33: 640000 | D33: =B33+C33 | E33: =E32+D33
A34: 8月 | B34: 250000 | C34: 800000 | D34: =B34+C34 | E34: =E33+D34
A35: 9月 | B35: 350000 | C35: 960000 | D35: =B35+C35 | E35: =E34+D35
A36: 10月 | B36: 450000 | C36: 1120000 | D36: =B36+C36 | E36: =E35+D36
A37: 11月 | B37: 500000 | C37: 1280000 | D37: =B37+C37 | E37: =E36+D37
A38: 12月 | B38: 600000 | C38: 1440000 | D38: =B38+C38 | E38: =E37+D38
A39: 合計 | B39: =SUM(B31:B38) | C39: =SUM(C31:C38) | D39: =B39+C39

Sheet メールテンプレート
A1: テンプレート名 | B1: 件名 | C1: 本文
A2: 資料送付メール（PF掲載フリープラン） | B2: ぺいほーむ 平屋専門プラットフォーム フリープランのご案内 | C2: ○○工務店 ○○様 お世話になっております。 平屋専門YouTubeメディア「ぺいほーむ」の○○です。 先ほどはお電話でお時間をいただき、ありがとうございました。 お電話でご案内いたしました、ぺいほーむプラットフォームの フリープラン（3ヶ月間完全無料）の詳細資料をお送りいたします。 ■ フリープランの概要 ・期間：2026年5月1日〜7月31日（3ヶ月間） ・費用：月額0円 / 成果報酬0円（完全無料） ・含まれるもの： - 工務店紹介ページ作成・公開 - 見学会・イベント告知（月1件） - 資料請求・見学会予約のリード送客 - AIチャットでの基本情報回答 - 月次閲覧レポート ■ 申込期限：4月20日（先着20社限定） 添付の資料をご確認いただき、 ご不明点がございましたらお気軽にご連絡ください。 ご検討のほど、よろしくお願いいたします。 ━━━━━━━━━━━━━━━ 株式会社wazeka ぺいほーむ事業部 ○○ ○○ TEL: XXX-XXXX-XXXX Email: info@payhome.jp ━━━━━━━━━━━━━━━
A3: 資料送付メール（マーケティング支援） | B3: ぺいほーむ マーケティング支援サービスのご案内 | C3: ○○工務店 ○○様 お世話になっております。 平屋専門YouTubeチャンネル「ぺいほーむ」の○○です。 先ほどはお電話でお時間をいただき、ありがとうございました。 登録者4万2千人・動画257本の実績を持つ 平屋専門の動画・SNSチームによるマーケティング支援の 詳細資料をお送りいたします。 ■ グロースプラン（月額15万円）の場合 ・ルームツアー動画 月1本（ぺいほーむchで公開＋御社に納品） ・ショート動画 月8本 ・Instagram毎日投稿 / TikTok週3投稿 ・LINE公式 月2配信 ・月次レポート 一般の動画制作会社に同内容を依頼すると月50〜70万円が相場です。 ぺいほーむなら月15万円で、67〜79%のコスト削減が可能です。 オンラインで30分ほど、御社の施工事例を拝見しながら 具体的なご提案をさせていただければと思います。 下記よりご都合のよい日時をお知らせいただけますか？ ご検討のほど、よろしくお願いいたします。 ━━━━━━━━━━━━━━━ 株式会社wazeka ぺいほーむ事業部 ○○ ○○ TEL: XXX-XXXX-XXXX Email: info@payhome.jp ━━━━━━━━━━━━━━━
A4: フォローメール（1週間後） | B4: 【ぺいほーむ】先日お送りした資料のご確認 | C4: ○○工務店 ○○様 お世話になっております。 ぺいほーむの○○です。 先日お送りした資料はご確認いただけましたでしょうか？ フリープランは先着20社限定で、 申込期限が4月20日となっております。 現在○社のお申込みをいただいている状況です。 ご不明点やご質問がございましたら、 お気軽にご連絡ください。 よろしくお願いいたします。 ━━━━━━━━━━━━━━━ 株式会社wazeka ぺいほーむ事業部 ━━━━━━━━━━━━━━━
A5: 商談お礼メール | B5: 【ぺいほーむ】本日の商談のお礼 | C5: ○○工務店 ○○様 お世話になっております。 ぺいほーむの○○です。 本日はお忙しい中、お時間をいただきありがとうございました。 本日お話しした内容をまとめます。 ■ ご提案内容 ・プラン名：○○プラン ・月額：○○円 ・開始時期：○月○日〜 ■ 次のステップ ・○○様にご確認いただく事項：○○ ・弊社で準備する事項：○○ ・次回のご連絡予定：○月○日 ご不明点がございましたら、いつでもご連絡ください。 引き続きよろしくお願いいたします。 ━━━━━━━━━━━━━━━ 株式会社wazeka ぺいほーむ事業部 ━━━━━━━━━━━━━━━
A6: フリープラン申込確認メール | B6: 【ぺいほーむ】フリープランお申込みの確認 | C6: ○○工務店 ○○様 お世話になっております。 ぺいほーむの○○です。 この度はフリープランにお申込みいただき、 誠にありがとうございます。 ■ お申込み内容 ・プラン：フリープラン（3ヶ月間完全無料） ・掲載開始日：2026年5月1日 ・無料期間：2026年5月1日〜7月31日 ■ 今後のスケジュール 1. 掲載に必要な情報のご提出（4月末まで） - 会社基本情報（確認済み） - 施工事例の写真 3〜5枚 - 御社の特徴・強み 2. 掲載ページの作成（弊社で対応） - 公開前に内容をご確認いただきます 3. 5月1日 プラットフォームリリース - 掲載開始＋リード送客開始 施工事例の写真は、メール添付またはファイル共有サービスで お送りいただければ幸いです。 ご不明点がございましたら、お気軽にご連絡ください。 今後ともよろしくお願いいたします。 ━━━━━━━━━━━━━━━ 株式会社wazeka ぺいほーむ事業部 ━━━━━━━━━━━━━━━
A7: 月次レポート送付メール | B7: 【ぺいほーむ】○月の掲載実績レポート | C7: ○○工務店 ○○様 お世話になっております。 ぺいほーむの○○です。 ○月の掲載実績レポートをお送りいたします。 ━━━━━━━━━━━━━━━ ■ ○月の実績 ━━━━━━━━━━━━━━━ ・ページ閲覧数：○○回（前月比 +○%） ・ユニークユーザー数：○○人 ・資料請求：○件 ・見学会予約：○件 ・AIチャットでの質問：○件 詳細は添付のレポートをご確認ください。 来月もより多くの平屋検討者に 御社の魅力をお届けできるよう努めてまいります。 ご質問やご要望がございましたら、 お気軽にご連絡ください。 ━━━━━━━━━━━━━━━ 株式会社wazeka ぺいほーむ事業部 ━━━━━━━━━━━━━━━
A8: 有料化事前通知メール（2ヶ月目に送付） | B8: 【ぺいほーむ】フリープラン期間終了のご案内 | C8: ○○工務店 ○○様 いつもぺいほーむをご利用いただきありがとうございます。 フリープランの期間が7月31日に終了いたします。 この2ヶ月間の御社の実績をお伝えします。 ━━━━━━━━━━━━━━━ ■ 御社ページの実績（5月〜6月） ━━━━━━━━━━━━━━━ ・ページ閲覧数：○○回 ・資料請求：○件 ・見学会予約：○件 ・AIチャットでの御社への質問：○件 ━━━━━━━━━━━━━━━ 8月1日以降は有料プランへの移行となります。 御社の反響実績から、以下のプランをおすすめいたします。 【おすすめ：○○プラン】 ・月額：○○円 ・資料請求：○○円/件 ・見学会来場：○○円/件 プランの詳細は添付資料をご確認ください。 ご不明点がございましたら、お気軽にご連絡ください。 ━━━━━━━━━━━━━━━ 株式会社wazeka ぺいほーむ事業部 ━━━━━━━━━━━━━━━
A9: 3ヶ月総合レポート＋有料プラン提案メール | B9: 【ぺいほーむ】3ヶ月間の総合レポート＋今後のプランのご案内 | C9: ○○工務店 ○○様 いつもぺいほーむをご利用いただきありがとうございます。 5月のリリースから3ヶ月間のフリープラン期間が 7月31日をもって終了いたします。 この3ヶ月間の御社の総合レポートをお送りいたします。 ━━━━━━━━━━━━━━━ ■ 3ヶ月間の総合実績 ━━━━━━━━━━━━━━━ ・ページ閲覧数（合計）：○○回 ・ユニークユーザー数：○○人 ・資料請求：○件 ・見学会予約：○件 ・AIチャットでの質問：○件 ■ ユーザー属性 ・年齢層：35〜44歳が○% ・エリア：○○市○%、○○市○% ━━━━━━━━━━━━━━━ 8月以降のプランとして、 御社の実績データから最もコストパフォーマンスの高い プランをご提案いたします。 【ご提案プラン：○○プラン】 ・月額：○○円 ・資料請求：○○円/件 ・見学会来場：○○円/件 ・推定月額コスト：○○円（直近3ヶ月のリード数から算出） 詳細は添付の総合レポートをご確認ください。 一度お会いして、データを見ながら 御社に最適なプランをご一緒に検討させてください。 下記の日程でお時間をいただけますか？ ・○月○日（○）○時〜 ・○月○日（○）○時〜 ・○月○日（○）○時〜 ご検討のほど、よろしくお願いいたします。 ━━━━━━━━━━━━━━━ 株式会社wazeka ぺいほーむ事業部 ━━━━━━━━━━━━━━━

Sheet 月次レポートテンプレート
A1: 月次レポートテンプレート（工務店送付用）
A3: 基本情報
A4: 対象企業 | B4: ○○工務店
A5: 対象期間 | B5: 2026年○月
A6: 作成日 | B6: 2026年○月○日
A8: 掲載実績
A9: ページ閲覧数 | B9: ○○回
A10: ユニークユーザー数 | B10: ○○人
A11: 平均滞在時間 | B11: ○分○秒
A12: 前月比 | B12: +○%
A14: リード実績
A15: 資料請求 | B15: ○件
A16: 見学会予約 | B16: ○件
A17: AIチャット質問 | B17: ○件
A18: 合計リード数 | B18: ○件
A20: ユーザー属性
A21: 年齢層 | B21: 35〜44歳が○%
A22: エリア | B22: ○○市○%
A23: デバイス | B23: スマホ○% / PC○%
A24: 流入元 | B24: YouTube○% / 検索○% / SNS○%
A26: 改善提案（掲載プロのみ）
A27: 現状の課題 | B27: ○○
A28: 改善案 | B28: ○○
A29: 次月の施策 | B29: ○○

Sheet ガントチャート
A1: 営業ガントチャート
A2: カテゴリ | B2: タスク | C2: W1 03/23 | D2: W2 03/30 | E2: W3 04/06 | F2: W4 04/13 | G2: W5 04/20 | H2: W6 04/27 | I2: W7 05/04 | J2: W8 05/11 | K2: W9 05/18 | L2: W10 05/25 | M2: W11 06/01 | N2: W12 06/08 | O2: W13 06/15 | P2: W14 06/22 | Q2: W15 06/29 | R2: W16 07/06 | S2: W17 07/13 | T2: W18 07/20 | U2: W19 07/27 | V2: W20 08/03 | W2: W21 08/10 | X2: W22 08/17 | Y2: W23 08/24 | Z2: W24 08/31 | AA2: W25 09/07 | AB2: W26 09/14 | AC2: W27 09/21 | AD2: W28 09/28 | AE2: W29 10/05 | AF2: W30 10/12 | AG2: W31 10/19 | AH2: W32 10/26 | AI2: W33 11/02 | AJ2: W34 11/09 | AK2: W35 11/16 | AL2: W36 11/23
A3: 営業準備 | B3: リスト作成・資料準備
A4: 営業準備 | B4: テレアポロープレ
A5: PF掲載 | B5: テレアポ（鹿児島）
A6: マーケ支援 | B6: テレアポ（全国）
A7: PF掲載 | B7: 商談・訪問
A8: マーケ支援 | B8: オンライン商談
A9: PF掲載 | B9: クロージング（〜4/20）
A10: 掲載準備 | B10: 掲載ページ作成
A11: 運用 | B11: 初回撮影（マーケ支援）
B12: ★ 5/1 リリース
A13: 運用 | B13: フリープラン運用
A14: レポート | B14: 月次レポート送付
A15: レポート | B15: 月次レポート送付
A16: PF掲載 | B16: 3ヶ月レポート＋有料化提案
B17: ★ 8/1 有料移行
A18: 運用 | B18: 有料運用＋クロスセル

Sheet 担当別Todo
A1: 右田 のタスク一覧
A2: ID | B2: タスク名 | C2: 期限 | D2: ステータス | E2: 優先度 | F2: メモ
A3: S-01 | B3: テレアポリスト作成（鹿児島50社） | C3: 2026/3/28 | D3: 未着手 | E3: 高
A4: S-03 | B4: 営業資料最終確認 | C4: 2026/3/28 | D4: 未着手 | E4: 高
A5: S-04 | B5: テレアポロープレ実施 | C5: 2026/3/28 | D5: 未着手 | E5: 高
A6: S-05 | B6: テレアポ実施（鹿児島）Week2 | C6: 2026/4/4 | D6: 未着手 | E6: 高
A7: S-07 | B7: 資料送付フォロー | C7: 2026/4/11 | D7: 未着手 | E7: 高
A8: S-08 | B8: テレアポ継続（鹿児島）Week3 | C8: 2026/4/11 | D8: 未着手 | E8: 高
A9: S-10 | B9: 訪問商談（PF掲載） | C9: 2026/4/18 | D9: 未着手 | E9: 高
A10: S-11 | B10: フリープラン申込クロージング | C10: 2026/4/20 | D10: 未着手 | E10: 高
A11: S-15 | B11: リリース最終準備 | C11: 2026/4/30 | D11: 未着手 | E11: 高
A12: S-16 | B12: 月次レポート作成（5月分） | C12: 2026/6/5 | D12: 未着手 | E12: 中
A13: S-17 | B13: 月次レポート作成（6月分） | C13: 2026/7/5 | D13: 未着手 | E13: 中
A14: S-18 | B14: 3ヶ月総合レポート作成 | C14: 2026/7/20 | D14: 未着手 | E14: 高
... A16: S-20 | B16: 有料化提案訪問 | C16: 2026/7/31 | D16: 未着手 | E16: 高
A19: 営業A のタスク一覧
A20: ID | B20: タスク名 | C20: 期限 | D20: ステータス | E20: 優先度 | F20: メモ
A21: S-02 | B21: テレアポリスト作成（全国30社） | C21: 2026/3/28 | D21: 未着手 | E21: 高
A22: S-04 | B22: テレアポロープレ実施 | C22: 2026/3/28 | D22: 未着手 | E22: 高
A23: S-06 | B23: テレアポ実施（全国）Week2 | C23: 2026/4/4 | D23: 未着手 | E23: 高
A24: S-09 | B24: オンライン商談（マーケ支援） | C24: 2026/4/11 | D24: 未着手 | E24: 高
A25: S-12 | B25: マーケ支援 契約クロージング | C25: 2026/4/20 | D25: 未着手 | E25: 高
A26: S-15 | B26: リリース最終準備 | C26: 2026/4/30 | D26: 未着手 | E26: 高
A29: 営業B のタスク一覧
A30: ID | B30: タスク名 | C30: 期限 | D30: ステータス | E30: 優先度 | F30: メモ
A31: S-04 | B31: テレアポロープレ実施 | C31: 2026/3/28 | D31: 未着手 | E31: 高
A32: S-15 | B32: リリース最終準備 | C32: 2026/4/30 | D32: 未着手 | E32: 高
A35: 制作 のタスク一覧
A36: ID | B36: タスク名 | C36: 期限 | D36: ステータス | E36: 優先度 | F36: メモ
A37: S-04 | B37: テレアポロープレ実施 | C37: 2026/3/28 | D37: 未着手 | E37: 高
A38: S-13 | B38: 掲載ページ作成 | C38: 2026/4/30 | D38: 未着手 | E38: 高
A39: S-14 | B39: 初回撮影（マーケ支援） | C39: 2026/4/30 | D39: 未着手 | E39: 高
A40: S-15 | B40: リリース最終準備 | C40: 2026/4/30 | D40: 未着手 | E40: 高

Sheet 使い方ガイド
A1: payhome_sales_v2 使い方ガイド
A3: シート名 | B3: 用途・使い方
A4: ダッシュボード | B4: 営業活動の全体像を一目で確認するシート。KPI、フェーズ、直近アクションを表示。数値は他シートから自動集計。
A5: 戦略概要 | B5: 事業の2本柱・フリープラン設計思想・競争優位性・収益シミュレーションの参照シート。社内共有や経営会議で使用。
A6: 料金プラン | B6: 全プランの料金体系を一覧化。営業時の参照用。セット割引・単発メニューも記載。
A7: テレアポ管理（鹿児島） | B7: 鹿児島の工務店へのテレアポ進捗を管理。コール日・結果・資料送付・商談・申込をステータスで追跡。
A8: テレアポ管理（全国） | B8: 全国の工務店へのマーケティング支援の営業進捗を管理。
A9: リードパイプライン | B9: 全ての見込み客をステージ別に管理。確度A〜Dで優先順位を可視化。
A10: タスク管理 | B10: 営業活動に関する全タスクを管理。担当者・優先度・期限・ステータスで進捗追跡。週次レビューで使用。
A11: KPI管理 | B11: 月次・週次のKPIを記録。目標と実績を比較し、改善アクションを検討。
A12: 収益シミュレーション | B12: 保守的・標準・楽観的の3シナリオで月次収益を予測。経営判断の参考に使用。
A13: メールテンプレート | B13: 営業メール8種のテンプレート。○○部分を書き換えて使用。
A14: 月次レポートテンプレート | B14: 工務店に送付する月次レポートのフォーマット。
... A16: 担当別Todo | B16: 各メンバーのタスクを一覧表示。週次ミーティングで進捗確認に使用。
A19: ステータスの定義
A20: ステータス | B20: 意味 | C20: 使用シート
A21: 未着手 | B21: 手をつけていない | C21: —
A22: 未コール | B22: まだ電話をしていない | C22: テレアポ管理シート
A23: コール済み | B23: 電話したが資料送付に至らず | C23: テレアポ管理シート
A24: 資料送付済み | B24: 資料を送付した | C24: テレアポ管理シート
A25: 商談調整中 | B25: 商談日程を調整中 | C25: テレアポ・パイプライン
A26: 商談済み | B26: 商談を実施した | C26: テレアポ・パイプライン
A27: 申込済み/契約済み | B27: 申込または契約が完了 | C27: テレアポ・パイプライン
A28: 見送り | B28: 今回は見送り | C28: テレアポ・パイプライン
A29: 進行中 | B29: 作業中 | C29: タスク管理
A30: 確認中 | B30: 成果物のレビュー待ち | C30: タスク管理
A31: 完了 | B31: 完了 | C31: タスク管理
A32: 保留 | B32: 他タスクの完了待ち | C32: タスク管理

Sheet 消費者フォローメール
A1: テンプレート名 | B1: 配信タイミング | C1: 件名 | D1: 本文 | E1: 目的 | F1: 配信方法
A2: お問い合わせ確認メール | B2: リード発生直後 | C2: 【ぺいほーむ】お問い合わせありがとうございます | D2: ○○様 ぺいほーむへのお問い合わせ、ありがとうございます。 ご依頼いただきました○○について、 ○○工務店様にお取り次ぎいたしました。 ○○工務店様より、1〜2営業日以内に ご連絡がございますので、少々お待ちください。 ぺいほーむでは、お客様の家づくりを 最後までサポートいたします。 ご質問やご不安なことがございましたら、 いつでもお気軽にご相談ください。 AIチャットでも24時間ご相談いただけます。 https://payhome.jp ━━━━━━━━━━━━━━━ ぺいほーむ（株式会社wazeka） Email: support@payhome.jp ━━━━━━━━━━━━━━━ ※このメールにお心当たりのない場合は、 お手数ですがこのメールを削除してください。 ※配信停止をご希望の場合は、以下のURLからお手続きください。 https://payhome.jp/unsubscribe?id=XXXX | E2: 関係の起点 | F2: 自動送信
A3: 対応確認メール | B3: 3日後 | C3: 【ぺいほーむ】○○工務店様からご連絡はありましたか？ | D3: ○○様 ぺいほーむです。 先日のお問い合わせ、ありがとうございました。 ○○工務店様からご連絡はございましたか？ もしまだ連絡がない場合は、 こちらから○○工務店様に確認いたしますので、 このメールにご返信ください。 また、他にも気になる工務店がございましたら、 ぺいほーむで検索・比較いただけます。 https://payhome.jp 引き続き、家づくりのお手伝いをさせてください。 ━━━━━━━━━━━━━━━ ぺいほーむ（株式会社wazeka） ━━━━━━━━━━━━━━━ ※配信停止をご希望の場合は、以下のURLからお手続きください。 https://payhome.jp/unsubscribe?id=XXXX | E3: 工務店対応確認 | F3: 自動送信
A4: 進捗確認メール | B4: 1週間後 | C4: 【ぺいほーむ】家づくりの進捗はいかがですか？ | D4: ○○様 ぺいほーむです。 家づくりのご検討は進んでいますか？ ○○工務店様との打ち合わせのご予定は 決まりましたでしょうか？ 家づくりを進める中で、 こんなお悩みはありませんか？ ・複数の工務店を比較したい ・平屋の間取りの参考事例を見たい ・住宅ローンのシミュレーションをしたい ・平屋の価格相場を知りたい ぺいほーむでは、これらの情報を 無料でご提供しています。 ▼ 平屋のルームツアー動画を見る https://youtube.com/@payhome ▼ 住宅ローンシミュレーター https://payhome.jp/simulator ▼ AIチャットで相談する https://payhome.jp お気軽にご利用ください。 ━━━━━━━━━━━━━━━ ぺいほーむ（株式会社wazeka） ━━━━━━━━━━━━━━━ ※配信停止をご希望の場合は、以下のURLからお手続きください。 https://payhome.jp/unsubscribe?id=XXXX | E4: 進捗確認 | F4: 自動送信
A5: 追加提案メール | B5: 2週間後 | C5: 【ぺいほーむ】他にも気になる工務店はありますか？ | D5: ○○様 ぺいほーむです。 家づくりのご検討、お疲れさまです。 平屋を建てる際、 多くの方が2〜3社を比較検討されています。 もし他にも気になる工務店がございましたら、 ぺいほーむで簡単に比較いただけます。 ▼ 鹿児島の平屋が得意な工務店一覧 https://payhome.jp/builders ▼ AIに相談して自分に合う工務店を見つける https://payhome.jp ご不明点がございましたら、 いつでもお気軽にご相談ください。 ━━━━━━━━━━━━━━━ ぺいほーむ（株式会社wazeka） ━━━━━━━━━━━━━━━ ※配信停止をご希望の場合は、以下のURLからお手続きください。 https://payhome.jp/unsubscribe?id=XXXX | E5: 追加紹介 | F5: 自動送信
A6: ステータス確認①メール | B6: 1ヶ月後 | C6: 【ぺいほーむ】家づくりの進捗を教えてください | D6: ○○様 ぺいほーむです。 お問い合わせから1ヶ月が経ちました。 家づくりの状況はいかがですか？ 1分で回答できるアンケートにご協力ください。 ▼ 現在の状況を教えてください（1分で完了） https://payhome.jp/survey?id=XXXX お答えいただいた内容に合わせて、 お役に立てる情報をお届けいたします。 ━━━━━━━━━━━━━━━ ぺいほーむ（株式会社wazeka） ━━━━━━━━━━━━━━━ ※配信停止をご希望の場合は、以下のURLからお手続きください。 https://payhome.jp/unsubscribe?id=XXXX | E6: ステータス確認 | F6: 自動送信
A7: ステータス確認②メール | B7: 2ヶ月後 | C7: 【ぺいほーむ】間取りや見積もりは進んでいますか？ | D7: ○○様 ぺいほーむです。 間取りや見積もりのご検討は 進んでいらっしゃいますか？ この時期に多い疑問をまとめました。 ■ 見積もりの比較ポイント ・坪単価だけでなく、付帯工事費も含めた総額で比較 ・地盤改良費は見積もりに含まれているか確認 ・アフターメンテナンスの条件も比較対象に ■ 平屋の間取りで後悔しないポイント ・家事動線は回遊できるか ・収納は十分か（壁面積が2階建てより少ない） ・将来の生活変化に対応できるか ▼ もっと詳しく知りたい方はAIに相談 https://payhome.jp ━━━━━━━━━━━━━━━ ぺいほーむ（株式会社wazeka） ━━━━━━━━━━━━━━━ ※配信停止をご希望の場合は、以下のURLからお手続きください。 https://payhome.jp/unsubscribe?id=XXXX | E7: ステータス確認 | F7: 自動送信
A8: 成約確認メール | B8: 3ヶ月後 | C8: 【ぺいほーむ】ご契約は決まりましたか？ | D8: ○○様 ぺいほーむです。 お問い合わせから3ヶ月が経ちました。 家づくりの状況はいかがですか？ ▼ 現在の状況を教えてください（1分で完了） https://payhome.jp/survey?id=XXXX □ まだ検討中です □ 工務店と打ち合わせ中です □ 契約しました！ □ 今回は見送りました ご契約された方には、 家づくりをもっと楽しむための情報を 引き続きお届けいたします。 まだご検討中の方には、 追加のご提案をさせていただきます。 いつでもお気軽にご相談ください。 ━━━━━━━━━━━━━━━ ぺいほーむ（株式会社wazeka） ━━━━━━━━━━━━━━━ ※配信停止をご希望の場合は、以下のURLからお手続きください。 https://payhome.jp/unsubscribe?id=XXXX | E8: 成約確認 | F8: 自動送信
A9: 長期フォローメール | B9: 6ヶ月後 | C9: 【ぺいほーむ】工事の進捗はいかがですか？ | D9: ○○様 ぺいほーむです。 新しいお住まいの工事は順調に進んでいますか？ 完成が近づくと、 家具やインテリアの準備も気になりますよね。 ぺいほーむでは、平屋の暮らしに役立つ情報を YouTubeやSNSで発信しています。 ▼ 平屋のルームツアー動画 https://youtube.com/@payhome 完成後、もしよろしければ お住まいの感想を聞かせてください。 ━━━━━━━━━━━━━━━ ぺいほーむ（株式会社wazeka） ━━━━━━━━━━━━━━━ ※配信停止をご希望の場合は、以下のURLからお手続きください。 https://payhome.jp/unsubscribe?id=XXXX | E9: 長期フォロー | F9: 自動送信
A10: 入居後フォローメール | B10: 12ヶ月後 | C10: 【ぺいほーむ】新居での暮らしはいかがですか？ | D10: ○○様 ぺいほーむです。 新居での暮らしはいかがですか？ 平屋の暮らしの感想を ぜひ聞かせていただけませんか？ ▼ 暮らしのアンケート（3分で完了） https://payhome.jp/review?id=XXXX いただいた感想は、 これから平屋を検討される方の 参考にさせていただきます。 また、お知り合いの方で 平屋を検討されている方がいらっしゃいましたら、 ぜひぺいほーむをご紹介ください。 https://payhome.jp 引き続き、快適な暮らしをお過ごしください。 ━━━━━━━━━━━━━━━ ぺいほーむ（株式会社wazeka） ━━━━━━━━━━━━━━━ ※配信停止をご希望の場合は、以下のURLからお手続きください。 https://payhome.jp/unsubscribe?id=XXXX | E10: 口コミ・紹介 | F10: 自動送信

Sheet 成約追跡
A1: リードID | B1: リード日 | C1: 消費者名 | D1: 紹介工務店 | E1: リード種別 | F1: ステータス | G1: 商談開始日 | H1: 契約日 | I1: 契約金額 | J1: 報酬率 | K1: 成約報酬額 | L1: 請求日 | M1: 入金日 | N1: 入金額 | O1: フォロー1回目 | P1: フォロー2回目 | Q1: フォロー3回目 | R1: 備考
K2: =I2*J2
K3: =I3*J3
K4: =I4*J4
K5: =I5*J5
K6: =I6*J6
K7: =I7*J7
K8: =I8*J8
K9: =I9*J9
K10: =I10*J10
K11: =I11*J11
K12: =I12*J12
K13: =I13*J13
... K31: =I31*J31

Sheet 有料化管理
A1: No | B1: 工務店名 | C1: フリープラン開始日 | D1: 3ヶ月経過日 | E1: 月間PV | F1: 累計リード件数 | G1: 有料化提案日 | H1: 提案プラン | I1: 工務店回答 | J1: 有料開始日 | K1: 月額 | L1: ステータス | M1: 担当 | N1: 備考
A2: 1 | D2: =IF(C2="","",C2+90)
A3: 2 | D3: =IF(C3="","",C3+90)
A4: 3 | D4: =IF(C4="","",C4+90)
A5: 4 | D5: =IF(C5="","",C5+90)
A6: 5 | D6: =IF(C6="","",C6+90)
A7: 6 | D7: =IF(C7="","",C7+90)
A8: 7 | D8: =IF(C8="","",C8+90)
A9: 8 | D9: =IF(C9="","",C9+90)
A10: 9 | D10: =IF(C10="","",C10+90)
A11: 10 | D11: =IF(C11="","",C11+90)
A12: 11 | D12: =IF(C12="","",C12+90)
A13: 12 | D13: =IF(C13="","",C13+90)
... A31: 30 | D31: =IF(C31="","",C31+90)
